Workbook

Sheet Datos
A1: BASE DE DATOS — TIEMPOS DE FALLA DE EQUIPOS ELECTRICOS
A2: Muestra de 200 unidades con censura por la derecha (tipo I). Tiempo en horas de operacion.
A3: Datos de entrada (azul = valores observados) | H3: Resumen de la muestra
A4: ID | B4: Tipo de equipo | C4: Tiempo observado t (h) | D4: Estado d (1=Falla, 0=Censurado) | E4: ln(t) | F4: Condicion | H4: N — unidades observadas | I4: =COUNT(C5:C204) -> 200
A5: 1 | B5: Banco de capacitores | C5: 528.3 | D5: 1 | E5: =LN(C5) -> 6.2696643 | F5: =IF(D5=1,"Falla","Censurado (sigue operando)") -> Falla | H5: r — numero de fallas | I5: =SUM(D5:D204) -> 122
A6: 2 | B6: Variador de velocidad | C6: 2040 | D6: 1 | E6: =LN(C6) -> 7.6207051 | F6: =IF(D6=1,"Falla","Censurado (sigue operando)") -> Falla | H6: Unidades censuradas | I6: =I4-I5 -> 78
A7: 3 | B7: Variador de velocidad | C7: 5368.1 | D7: 1 | E7: =LN(C7) -> 8.5882293 | F7: =IF(D7=1,"Falla","Censurado (sigue operando)") -> Falla | H7: % de censura | I7: =I6/I4 -> 0.39
A8: 4 | B8: Banco de capacitores | C8: 3449.1 | D8: 1 | E8: =LN(C8) -> 8.1458686 | F8: =IF(D8=1,"Falla","Censurado (sigue operando)") -> Falla | H8: t minimo (h) | I8: =MIN(C5:C204) -> 401.7
A9: 5 | B9: Interruptor de potencia | C9: 2624.6 | D9: 0 | E9: =LN(C9) -> 7.8726838 | F9: =IF(D9=1,"Falla","Censurado (sigue operando)") -> Censurado (sigue operando) | H9: t maximo (h) | I9: =MAX(C5:C204) -> 9165.7
A10: 6 | B10: Variador de velocidad | C10: 2063.6 | D10: 1 | E10: =LN(C10) -> 7.6322073 | F10: =IF(D10=1,"Falla","Censurado (sigue operando)") -> Falla | H10: Suma de t (h) | I10: =SUM(C5:C204) -> 700388.5
A11: 7 | B11: Banco de capacitores | C11: 2968.1 | D11: 1 | E11: =LN(C11) -> 7.9956773 | F11: =IF(D11=1,"Falla","Censurado (sigue operando)") -> Falla | H11: S1 = SUM(d*ln(t)) | I11: =SUMPRODUCT($D$5:$D$204,$E$5:$E$204) -> 974.90977
A12: 8 | B12: Motor de induccion MT | C12: 3955.9 | D12: 0 | E12: =LN(C12) -> 8.2829634 | F12: =IF(D12=1,"Falla","Censurado (sigue operando)") -> Censurado (sigue operando)
A13: 9 | B13: Transformador de distribucion | C13: 3890.5 | D13: 1 | E13: =LN(C13) -> 8.266293 | F13: =IF(D13=1,"Falla","Censurado (sigue operando)") -> Falla | H13: Nota
A14: 10 | B14: Motor de induccion MT | C14: 5854 | D14: 1 | E14: =LN(C14) -> 8.6748805 | F14: =IF(D14=1,"Falla","Censurado (sigue operando)") -> Falla | H14: Una observacion censurada indica que la unidad seguia operando al cierre del estudio o fue retirada por causas ajenas a la falla. No se descarta: aporta informacion de que sobrevivio al menos t horas.
A15: 11 | B15: Motor de induccion MT | C15: 2361.4 | D15: 1 | E15: =LN(C15) -> 7.7670099 | F15: =IF(D15=1,"Falla","Censurado (sigue operando)") -> Falla
A16: 12 | B16: Banco de capacitores | C16: 4920.8 | D16: 0 | E16: =LN(C16) -> 8.5012264 | F16: =IF(D16=1,"Falla","Censurado (sigue operando)") -> Censurado (sigue operando)
A17: 13 | B17: Banco de capacitores | C17: 2338.7 | D17: 1 | E17: =LN(C17) -> 7.7573505 | F17: =IF(D17=1,"Falla","Censurado (sigue operando)") -> Falla
A18: 14 | B18: Transformador de distribucion | C18: 3224.7 | D18: 0 | E18: =LN(C18) -> 8.0785952 | F18: =IF(D18=1,"Falla","Censurado (sigue operando)") -> Censurado (sigue operando)
A19: 15 | B19: Interruptor de potencia | C19: 2587.9 | D19: 0 | E19: =LN(C19) -> 7.858602 | F19: =IF(D19=1,"Falla","Censurado (sigue operando)") -> Censurado (sigue operando)
A20: 16 | B20: Banco de capacitores | C20: 4776.7 | D20: 1 | E20: =LN(C20) -> 8.4715052 | F20: =IF(D20=1,"Falla","Censurado (sigue operando)") -> Falla
A21: 17 | B21: Transformador de distribucion | C21: 2298.2 | D21: 0 | E21: =LN(C21) -> 7.7398815 | F21: =IF(D21=1,"Falla","Censurado (sigue operando)") -> Censurado (sigue operando)
A22: 18 | B22: Variador de velocidad | C22: 2505.5 | D22: 1 | E22: =LN(C22) -> 7.8262436 | F22: =IF(D22=1,"Falla","Censurado (sigue operando)") -> Falla
A23: 19 | B23: Transformador de distribucion | C23: 941.7 | D23: 1 | E23: =LN(C23) -> 6.8476868 | F23: =IF(D23=1,"Falla","Censurado (sigue operando)") -> Falla
A24: 20 | B24: Interruptor de potencia | C24: 5202.6 | D24: 0 | E24: =LN(C24) -> 8.5569138 | F24: =IF(D24=1,"Falla","Censurado (sigue operando)") -> Censurado (sigue operando)
A25: 21 | B25: Banco de capacitores | C25: 455.5 | D25: 1 | E25: =LN(C25) -> 6.1213957 | F25: =IF(D25=1,"Falla","Censurado (sigue operando)") -> Falla
A26: 22 | B26: Motor de induccion MT | C26: 2474.1 | D26: 1 | E26: =LN(C26) -> 7.813632 | F26: =IF(D26=1,"Falla","Censurado (sigue operando)") -> Falla
... A204: 200 | B204: Transformador de distribucion | C204: 5553.6 | D204: 1 | E204: =LN(C204) -> 8.6222016 | F204: =IF(D204=1,"Falla","Censurado (sigue operando)") -> Falla

Sheet Metodo_Grafico
A1: METODO GRAFICO — PAPEL DE PROBABILIDAD WEIBULL Y REGRESION DE RANGOS
A2: Rangos medianos con ajuste de Johnson para censura. Linealizacion: ln(-ln(1-F)) = b*ln(t) - b*ln(n).
O3: Regresion por minimos cuadrados (solo fallas, mascara d)
A4: N = | B4: =COUNT(Datos!$C$5:$C$204) -> 200
A5: r = | B5: =SUM(Datos!$D$5:$D$204) -> 122 | O5: r (pares usados) | P5: =SUM($C$8:$C$207) -> 122
K6: Metodo Grafico | O6: Sx = SUM(d*x) | P6: =SUMPRODUCT($C$8:$C$207,$H$8:$H$207) -> 974.90977
A7: j (orden) | B7: t(j) ordenado (h) | C7: d | D7: n(j) = N-j+1 | E7: Incremento I(j) | F7: Rango ajustado AR(j) | G7: Rango mediano F(tj) | H7: x = ln(t) | I7: y = ln(-ln(1-F)) | K7: x (solo fallas) | L7: y (solo fallas) | M7: y ajustado | O7: Sy = SUM(d*y) | P7: =SUMPRODUCT($C$8:$C$207,$I$8:$I$207) -> -128.21331
A8: 1 | B8: =SMALL(Datos!$C$5:$C$204,A8) -> 401.7 | C8: =INDEX(Datos!$D$5:$D$204,MATCH(B8,Datos!$C$5:$C$204,0)) -> 1 | D8: =$B$4-A8+1 -> 200 | E8: =IF(C8=1,($B$4+1-0)/(1+D8),0) -> 1 | F8: =0+E8 -> 1 | G8: =IF(C8=1,(F8-0.3)/($B$4+0.4),0) -> 0.003493014 | H8: =LN(B8) -> 5.9957055 | I8: =IF(C8=1,LN(-LN(1-G8)),0) -> -5.6552413 | K8: =IF(C8=1,H8,NA()) -> 5.9957055 | L8: =IF(C8=1,I8,NA()) -> -5.6552413 | M8: =IF(C8=1,$P$12*H8+$P$13,"") -> -4.8604273 | O8: Sxy = SUM(d*x*y) | P8: =SUMPRODUCT($C$8:$C$207,$H$8:$H$207,$I$8:$I$207) -> -926.46857
A9: 2 | B9: =SMALL(Datos!$C$5:$C$204,A9) -> 449.3 | C9: =INDEX(Datos!$D$5:$D$204,MATCH(B9,Datos!$C$5:$C$204,0)) -> 1 | D9: =$B$4-A9+1 -> 199 | E9: =IF(C9=1,($B$4+1-F8)/(1+D9),0) -> 1 | F9: =F8+E9 -> 2 | G9: =IF(C9=1,(F9-0.3)/($B$4+0.4),0) -> 0.0084830339 | H9: =LN(B9) -> 6.1076908 | I9: =IF(C9=1,LN(-LN(1-G9)),0) -> -4.7654305 | K9: =IF(C9=1,H9,NA()) -> 6.1076908 | L9: =IF(C9=1,I9,NA()) -> -4.7654305 | M9: =IF(C9=1,$P$12*H9+$P$13,"") -> -4.6466272 | O9: Sxx = SUM(d*x^2) | P9: =SUMPRODUCT($C$8:$C$207,$H$8:$H$207,$H$8:$H$207) -> 7841.9453
A10: 3 | B10: =SMALL(Datos!$C$5:$C$204,A10) -> 455.5 | C10: =INDEX(Datos!$D$5:$D$204,MATCH(B10,Datos!$C$5:$C$204,0)) -> 1 | D10: =$B$4-A10+1 -> 198 | E10: =IF(C10=1,($B$4+1-F9)/(1+D10),0) -> 1 | F10: =F9+E10 -> 3 | G10: =IF(C10=1,(F10-0.3)/($B$4+0.4),0) -> 0.013473054 | H10: =LN(B10) -> 6.1213957 | I10: =IF(C10=1,LN(-LN(1-G10)),0) -> -4.3002889 | K10: =IF(C10=1,H10,NA()) -> 6.1213957 | L10: =IF(C10=1,I10,NA()) -> -4.3002889 | M10: =IF(C10=1,$P$12*H10+$P$13,"") -> -4.6204621 | O10: Syy = SUM(d*y^2) | P10: =SUMPRODUCT($C$8:$C$207,$I$8:$I$207,$I$8:$I$207) -> 323.93943
A11: 4 | B11: =SMALL(Datos!$C$5:$C$204,A11) -> 528.3 | C11: =INDEX(Datos!$D$5:$D$204,MATCH(B11,Datos!$C$5:$C$204,0)) -> 1 | D11: =$B$4-A11+1 -> 197 | E11: =IF(C11=1,($B$4+1-F10)/(1+D11),0) -> 1 | F11: =F10+E11 -> 4 | G11: =IF(C11=1,(F11-0.3)/($B$4+0.4),0) -> 0.018463074 | H11: =LN(B11) -> 6.2696643 | I11: =IF(C11=1,LN(-LN(1-G11)),0) -> -3.9826792 | K11: =IF(C11=1,H11,NA()) -> 6.2696643 | L11: =IF(C11=1,I11,NA()) -> -3.9826792 | M11: =IF(C11=1,$P$12*H11+$P$13,"") -> -4.3373906
A12: 5 | B12: =SMALL(Datos!$C$5:$C$204,A12) -> 602 | C12: =INDEX(Datos!$D$5:$D$204,MATCH(B12,Datos!$C$5:$C$204,0)) -> 1 | D12: =$B$4-A12+1 -> 196 | E12: =IF(C12=1,($B$4+1-F11)/(1+D12),0) -> 1 | F12: =F11+E12 -> 5 | G12: =IF(C12=1,(F12-0.3)/($B$4+0.4),0) -> 0.023453094 | H12: =LN(B12) -> 6.4002574 | I12: =IF(C12=1,LN(-LN(1-G12)),0) -> -3.7409101 | K12: =IF(C12=1,H12,NA()) -> 6.4002574 | L12: =IF(C12=1,I12,NA()) -> -3.7409101 | M12: =IF(C12=1,$P$12*H12+$P$13,"") -> -4.0880648 | O12: Pendiente m | P12: =($P$5*$P$8-$P$6*$P$7)/($P$5*$P$9-$P$6^2) -> 1.9091803
A13: 6 | B13: =SMALL(Datos!$C$5:$C$204,A13) -> 707.6 | C13: =INDEX(Datos!$D$5:$D$204,MATCH(B13,Datos!$C$5:$C$204,0)) -> 1 | D13: =$B$4-A13+1 -> 195 | E13: =IF(C13=1,($B$4+1-F12)/(1+D13),0) -> 1 | F13: =F12+E13 -> 6 | G13: =IF(C13=1,(F13-0.3)/($B$4+0.4),0) -> 0.028443114 | H13: =LN(B13) -> 6.561879 | I13: =IF(C13=1,LN(-LN(1-G13)),0) -> -3.5454562 | K13: =IF(C13=1,H13,NA()) -> 6.561879 | L13: =IF(C13=1,I13,NA()) -> -3.5454562 | M13: =IF(C13=1,$P$12*H13+$P$13,"") -> -3.7795002 | O13: Intercepto c | P13: =($P$7-$P$12*$P$6)/$P$5 -> -16.30731
A14: 7 | B14: =SMALL(Datos!$C$5:$C$204,A14) -> 820.7 | C14: =INDEX(Datos!$D$5:$D$204,MATCH(B14,Datos!$C$5:$C$204,0)) -> 1 | D14: =$B$4-A14+1 -> 194 | E14: =IF(C14=1,($B$4+1-F13)/(1+D14),0) -> 1 | F14: =F13+E14 -> 7 | G14: =IF(C14=1,(F14-0.3)/($B$4+0.4),0) -> 0.033433134 | H14: =LN(B14) -> 6.7101576 | I14: =IF(C14=1,LN(-LN(1-G14)),0) -> -3.3812536 | K14: =IF(C14=1,H14,NA()) -> 6.7101576 | L14: =IF(C14=1,I14,NA()) -> -3.3812536 | M14: =IF(C14=1,$P$12*H14+$P$13,"") -> -3.4964094
A15: 8 | B15: =SMALL(Datos!$C$5:$C$204,A15) -> 871.6 | C15: =INDEX(Datos!$D$5:$D$204,MATCH(B15,Datos!$C$5:$C$204,0)) -> 1 | D15: =$B$4-A15+1 -> 193 | E15: =IF(C15=1,($B$4+1-F14)/(1+D15),0) -> 1 | F15: =F14+E15 -> 8 | G15: =IF(C15=1,(F15-0.3)/($B$4+0.4),0) -> 0.038423154 | H15: =LN(B15) -> 6.7703306 | I15: =IF(C15=1,LN(-LN(1-G15)),0) -> -3.2395686 | K15: =IF(C15=1,H15,NA()) -> 6.7703306 | L15: =IF(C15=1,I15,NA()) -> -3.2395686 | M15: =IF(C15=1,$P$12*H15+$P$13,"") -> -3.3815284 | O15: BETA estimado = m | P15: =$P$12 -> 1.9091803
A16: 9 | B16: =SMALL(Datos!$C$5:$C$204,A16) -> 873.6 | C16: =INDEX(Datos!$D$5:$D$204,MATCH(B16,Datos!$C$5:$C$204,0)) -> 1 | D16: =$B$4-A16+1 -> 192 | E16: =IF(C16=1,($B$4+1-F15)/(1+D16),0) -> 1 | F16: =F15+E16 -> 9 | G16: =IF(C16=1,(F16-0.3)/($B$4+0.4),0) -> 0.043413174 | H16: =LN(B16) -> 6.7726226 | I16: =IF(C16=1,LN(-LN(1-G16)),0) -> -3.1148826 | K16: =IF(C16=1,H16,NA()) -> 6.7726226 | L16: =IF(C16=1,I16,NA()) -> -3.1148826 | M16: =IF(C16=1,$P$12*H16+$P$13,"") -> -3.3771525 | O16: ETA estimado = EXP(-c/m) (h) | P16: =EXP(-$P$13/$P$12) -> 5123.1482
A17: 10 | B17: =SMALL(Datos!$C$5:$C$204,A17) -> 941.7 | C17: =INDEX(Datos!$D$5:$D$204,MATCH(B17,Datos!$C$5:$C$204,0)) -> 1 | D17: =$B$4-A17+1 -> 191 | E17: =IF(C17=1,($B$4+1-F16)/(1+D17),0) -> 1 | F17: =F16+E17 -> 10 | G17: =IF(C17=1,(F17-0.3)/($B$4+0.4),0) -> 0.048403194 | H17: =LN(B17) -> 6.8476868 | I17: =IF(C17=1,LN(-LN(1-G17)),0) -> -3.0034851 | K17: =IF(C17=1,H17,NA()) -> 6.8476868 | L17: =IF(C17=1,I17,NA()) -> -3.0034851 | M17: =IF(C17=1,$P$12*H17+$P$13,"") -> -3.2338416
A18: 11 | B18: =SMALL(Datos!$C$5:$C$204,A18) -> 960.8 | C18: =INDEX(Datos!$D$5:$D$204,MATCH(B18,Datos!$C$5:$C$204,0)) -> 0 | D18: =$B$4-A18+1 -> 190 | E18: =IF(C18=1,($B$4+1-F17)/(1+D18),0) -> 0 | F18: =F17+E18 -> 10 | G18: =IF(C18=1,(F18-0.3)/($B$4+0.4),0) -> 0 | H18: =LN(B18) -> 6.8677663 | I18: =IF(C18=1,LN(-LN(1-G18)),0) -> 0 | K18: =IF(C18=1,H18,NA()) -> #N/A | L18: =IF(C18=1,I18,NA()) -> #N/A | M18: =IF(C18=1,$P$12*H18+$P$13,"") | O18: Coef. correlacion rho | P18: =($P$5*$P$8-$P$6*$P$7)/SQRT(($P$5*$P$9-$P$6^2)*($P$5*$P$10-$P$7^2)) -> 0.99491076
A19: 12 | B19: =SMALL(Datos!$C$5:$C$204,A19) -> 1024.2 | C19: =INDEX(Datos!$D$5:$D$204,MATCH(B19,Datos!$C$5:$C$204,0)) -> 0 | D19: =$B$4-A19+1 -> 189 | E19: =IF(C19=1,($B$4+1-F18)/(1+D19),0) -> 0 | F19: =F18+E19 -> 10 | G19: =IF(C19=1,(F19-0.3)/($B$4+0.4),0) -> 0 | H19: =LN(B19) -> 6.9316671 | I19: =IF(C19=1,LN(-LN(1-G19)),0) -> 0 | K19: =IF(C19=1,H19,NA()) -> #N/A | L19: =IF(C19=1,I19,NA()) -> #N/A | M19: =IF(C19=1,$P$12*H19+$P$13,"") | O19: R cuadrado | P19: =$P$18^2 -> 0.98984743
A20: 13 | B20: =SMALL(Datos!$C$5:$C$204,A20) -> 1073.5 | C20: =INDEX(Datos!$D$5:$D$204,MATCH(B20,Datos!$C$5:$C$204,0)) -> 0 | D20: =$B$4-A20+1 -> 188 | E20: =IF(C20=1,($B$4+1-F19)/(1+D20),0) -> 0 | F20: =F19+E20 -> 10 | G20: =IF(C20=1,(F20-0.3)/($B$4+0.4),0) -> 0 | H20: =LN(B20) -> 6.9786796 | I20: =IF(C20=1,LN(-LN(1-G20)),0) -> 0 | K20: =IF(C20=1,H20,NA()) -> #N/A | L20: =IF(C20=1,I20,NA()) -> #N/A | M20: =IF(C20=1,$P$12*H20+$P$13,"")
A21: 14 | B21: =SMALL(Datos!$C$5:$C$204,A21) -> 1077.1 | C21: =INDEX(Datos!$D$5:$D$204,MATCH(B21,Datos!$C$5:$C$204,0)) -> 1 | D21: =$B$4-A21+1 -> 187 | E21: =IF(C21=1,($B$4+1-F20)/(1+D21),0) -> 1.0159574 | F21: =F20+E21 -> 11.015957 | G21: =IF(C21=1,(F21-0.3)/($B$4+0.4),0) -> 0.053472842 | H21: =LN(B21) -> 6.9820275 | I21: =IF(C21=1,LN(-LN(1-G21)),0) -> -2.9012294 | K21: =IF(C21=1,H21,NA()) -> 6.9820275 | L21: =IF(C21=1,I21,NA()) -> -2.9012294 | M21: =IF(C21=1,$P$12*H21+$P$13,"") -> -2.9773608 | O21: MTTF = eta*GAMMA(1+1/beta) (h) | P21: =$P$16*EXP(GAMMALN(1+1/$P$15)) -> 4545.4076
A22: 15 | B22: =SMALL(Datos!$C$5:$C$204,A22) -> 1099.2 | C22: =INDEX(Datos!$D$5:$D$204,MATCH(B22,Datos!$C$5:$C$204,0)) -> 1 | D22: =$B$4-A22+1 -> 186 | E22: =IF(C22=1,($B$4+1-F21)/(1+D22),0) -> 1.0159574 | F22: =F21+E22 -> 12.031915 | G22: =IF(C22=1,(F22-0.3)/($B$4+0.4),0) -> 0.058542489 | H22: =LN(B22) -> 7.0023379 | I22: =IF(C22=1,LN(-LN(1-G22)),0) -> -2.8079911 | K22: =IF(C22=1,H22,NA()) -> 7.0023379 | L22: =IF(C22=1,I22,NA()) -> -2.8079911 | M22: =IF(C22=1,$P$12*H22+$P$13,"") -> -2.9385846 | O22: Mediana = eta*LN(2)^(1/beta) (h) | P22: =$P$16*LN(2)^(1/$P$15) -> 4228.2795
A23: 16 | B23: =SMALL(Datos!$C$5:$C$204,A23) -> 1133.3 | C23: =INDEX(Datos!$D$5:$D$204,MATCH(B23,Datos!$C$5:$C$204,0)) -> 0 | D23: =$B$4-A23+1 -> 185 | E23: =IF(C23=1,($B$4+1-F22)/(1+D23),0) -> 0 | F23: =F22+E23 -> 12.031915 | G23: =IF(C23=1,(F23-0.3)/($B$4+0.4),0) -> 0 | H23: =LN(B23) -> 7.032889 | I23: =IF(C23=1,LN(-LN(1-G23)),0) -> 0 | K23: =IF(C23=1,H23,NA()) -> #N/A | L23: =IF(C23=1,I23,NA()) -> #N/A | M23: =IF(C23=1,$P$12*H23+$P$13,"") | O23: Vida B10 = eta*(-LN(0.9))^(1/beta) | P23: =$P$16*(-LN(0.9))^(1/$P$15) -> 1576.2688
A24: 17 | B24: =SMALL(Datos!$C$5:$C$204,A24) -> 1161.6 | C24: =INDEX(Datos!$D$5:$D$204,MATCH(B24,Datos!$C$5:$C$204,0)) -> 1 | D24: =$B$4-A24+1 -> 184 | E24: =IF(C24=1,($B$4+1-F23)/(1+D24),0) -> 1.0214491 | F24: =F23+E24 -> 13.053364 | G24: =IF(C24=1,(F24-0.3)/($B$4+0.4),0) -> 0.063639541 | H24: =LN(B24) -> 7.0575536 | I24: =IF(C24=1,LN(-LN(1-G24)),0) -> -2.7218231 | K24: =IF(C24=1,H24,NA()) -> 7.0575536 | L24: =IF(C24=1,I24,NA()) -> -2.7218231 | M24: =IF(C24=1,$P$12*H24+$P$13,"") -> -2.8331678
A25: 18 | B25: =SMALL(Datos!$C$5:$C$204,A25) -> 1196.6 | C25: =INDEX(Datos!$D$5:$D$204,MATCH(B25,Datos!$C$5:$C$204,0)) -> 0 | D25: =$B$4-A25+1 -> 183 | E25: =IF(C25=1,($B$4+1-F24)/(1+D25),0) -> 0 | F25: =F24+E25 -> 13.053364 | G25: =IF(C25=1,(F25-0.3)/($B$4+0.4),0) -> 0 | H25: =LN(B25) -> 7.0872395 | I25: =IF(C25=1,LN(-LN(1-G25)),0) -> 0 | K25: =IF(C25=1,H25,NA()) -> #N/A | L25: =IF(C25=1,I25,NA()) -> #N/A | M25: =IF(C25=1,$P$12*H25+$P$13,"") | O25: Como leer este metodo
A26: 19 | B26: =SMALL(Datos!$C$5:$C$204,A26) -> 1230.9 | C26: =INDEX(Datos!$D$5:$D$204,MATCH(B26,Datos!$C$5:$C$204,0)) -> 1 | D26: =$B$4-A26+1 -> 182 | E26: =IF(C26=1,($B$4+1-F25)/(1+D26),0) -> 1.0270308 | F26: =F25+E26 -> 14.080395 | G26: =IF(C26=1,(F26-0.3)/($B$4+0.4),0) -> 0.068764445 | H26: =LN(B26) -> 7.1155009 | I26: =IF(C26=1,LN(-LN(1-G26)),0) -> -2.6416584 | K26: =IF(C26=1,H26,NA()) -> 7.1155009 | L26: =IF(C26=1,I26,NA()) -> -2.6416584 | M26: =IF(C26=1,$P$12*H26+$P$13,"") -> -2.7225361 | O26: 1) Se ordenan los 200 tiempos de menor a mayor. 2) Los censurados no reciben rango, pero desplazan el rango de las fallas posteriores mediante el incremento de Johnson I = (N+1-AR_anterior)/(1+n_j). 3) El rango mediano F(tj) = (AR-0.3)/(N+0.4) estima la probabilidad acumulada de falla. 4) Al graficar y = ln(-ln(1-F)) contra x = ln(t), una Weibull debe dar una recta: la pendiente es BETA y el intercepto vale -BETA*ln(ETA). 5) R cuadrado cercano a 1 respalda el supuesto Weibull; curvatura sistematica sugiere mezcla de modos de falla.
A27: 20 | B27: =SMALL(Datos!$C$5:$C$204,A27) -> 1240.7 | C27: =INDEX(Datos!$D$5:$D$204,MATCH(B27,Datos!$C$5:$C$204,0)) -> 0 | D27: =$B$4-A27+1 -> 181 | E27: =IF(C27=1,($B$4+1-F26)/(1+D27),0) -> 0 | F27: =F26+E27 -> 14.080395 | G27: =IF(C27=1,(F27-0.3)/($B$4+0.4),0) -> 0 | H27: =LN(B27) -> 7.123431 | I27: =IF(C27=1,LN(-LN(1-G27)),0) -> 0 | K27: =IF(C27=1,H27,NA()) -> #N/A | L27: =IF(C27=1,I27,NA()) -> #N/A | M27: =IF(C27=1,$P$12*H27+$P$13,"")
A28: 21 | B28: =SMALL(Datos!$C$5:$C$204,A28) -> 1265.2 | C28: =INDEX(Datos!$D$5:$D$204,MATCH(B28,Datos!$C$5:$C$204,0)) -> 0 | D28: =$B$4-A28+1 -> 180 | E28: =IF(C28=1,($B$4+1-F27)/(1+D28),0) -> 0 | F28: =F27+E28 -> 14.080395 | G28: =IF(C28=1,(F28-0.3)/($B$4+0.4),0) -> 0 | H28: =LN(B28) -> 7.1429855 | I28: =IF(C28=1,LN(-LN(1-G28)),0) -> 0 | K28: =IF(C28=1,H28,NA()) -> #N/A | L28: =IF(C28=1,I28,NA()) -> #N/A | M28: =IF(C28=1,$P$12*H28+$P$13,"")
A29: 22 | B29: =SMALL(Datos!$C$5:$C$204,A29) -> 1308.3 | C29: =INDEX(Datos!$D$5:$D$204,MATCH(B29,Datos!$C$5:$C$204,0)) -> 0 | D29: =$B$4-A29+1 -> 179 | E29: =IF(C29=1,($B$4+1-F28)/(1+D29),0) -> 0 | F29: =F28+E29 -> 14.080395 | G29: =IF(C29=1,(F29-0.3)/($B$4+0.4),0) -> 0 | H29: =LN(B29) -> 7.1764839 | I29: =IF(C29=1,LN(-LN(1-G29)),0) -> 0 | K29: =IF(C29=1,H29,NA()) -> #N/A | L29: =IF(C29=1,I29,NA()) -> #N/A | M29: =IF(C29=1,$P$12*H29+$P$13,"")
A30: 23 | B30: =SMALL(Datos!$C$5:$C$204,A30) -> 1360.3 | C30: =INDEX(Datos!$D$5:$D$204,MATCH(B30,Datos!$C$5:$C$204,0)) -> 1 | D30: =$B$4-A30+1 -> 178 | E30: =IF(C30=1,($B$4+1-F29)/(1+D30),0) -> 1.0442436 | F30: =F29+E30 -> 15.124638 | G30: =IF(C30=1,(F30-0.3)/($B$4+0.4),0) -> 0.073975242 | H30: =LN(B30) -> 7.2154605 | I30: =IF(C30=1,LN(-LN(1-G30)),0) -> -2.5658438 | K30: =IF(C30=1,H30,NA()) -> 7.2154605 | L30: =IF(C30=1,I30,NA()) -> -2.5658438 | M30: =IF(C30=1,$P$12*H30+$P$13,"") -> -2.5316951
A31: 24 | B31: =SMALL(Datos!$C$5:$C$204,A31) -> 1392.9 | C31: =INDEX(Datos!$D$5:$D$204,MATCH(B31,Datos!$C$5:$C$204,0)) -> 1 | D31: =$B$4-A31+1 -> 177 | E31: =IF(C31=1,($B$4+1-F30)/(1+D31),0) -> 1.0442436 | F31: =F30+E31 -> 16.168882 | G31: =IF(C31=1,(F31-0.3)/($B$4+0.4),0) -> 0.079186038 | H31: =LN(B31) -> 7.2391432 | I31: =IF(C31=1,LN(-LN(1-G31)),0) -> -2.4949902 | K31: =IF(C31=1,H31,NA()) -> 7.2391432 | L31: =IF(C31=1,I31,NA()) -> -2.4949902 | M31: =IF(C31=1,$P$12*H31+$P$13,"") -> -2.4864806
A32: 25 | B32: =SMALL(Datos!$C$5:$C$204,A32) -> 1441.9 | C32: =INDEX(Datos!$D$5:$D$204,MATCH(B32,Datos!$C$5:$C$204,0)) -> 1 | D32: =$B$4-A32+1 -> 176 | E32: =IF(C32=1,($B$4+1-F31)/(1+D32),0) -> 1.0442436 | F32: =F31+E32 -> 17.213126 | G32: =IF(C32=1,(F32-0.3)/($B$4+0.4),0) -> 0.084396834 | H32: =LN(B32) -> 7.273717 | I32: =IF(C32=1,LN(-LN(1-G32)),0) -> -2.4284632 | K32: =IF(C32=1,H32,NA()) -> 7.273717 | L32: =IF(C32=1,I32,NA()) -> -2.4284632 | M32: =IF(C32=1,$P$12*H32+$P$13,"") -> -2.420473
A33: 26 | B33: =SMALL(Datos!$C$5:$C$204,A33) -> 1442.2 | C33: =INDEX(Datos!$D$5:$D$204,MATCH(B33,Datos!$C$5:$C$204,0)) -> 1 | D33: =$B$4-A33+1 -> 175 | E33: =IF(C33=1,($B$4+1-F32)/(1+D33),0) -> 1.0442436 | F33: =F32+E33 -> 18.257369 | G33: =IF(C33=1,(F33-0.3)/($B$4+0.4),0) -> 0.089607631 | H33: =LN(B33) -> 7.273925 | I33: =IF(C33=1,LN(-LN(1-G33)),0) -> -2.3657422 | K33: =IF(C33=1,H33,NA()) -> 7.273925 | L33: =IF(C33=1,I33,NA()) -> -2.3657422 | M33: =IF(C33=1,$P$12*H33+$P$13,"") -> -2.4200759
A34: 27 | B34: =SMALL(Datos!$C$5:$C$204,A34) -> 1449.1 | C34: =INDEX(Datos!$D$5:$D$204,MATCH(B34,Datos!$C$5:$C$204,0)) -> 0 | D34: =$B$4-A34+1 -> 174 | E34: =IF(C34=1,($B$4+1-F33)/(1+D34),0) -> 0 | F34: =F33+E34 -> 18.257369 | G34: =IF(C34=1,(F34-0.3)/($B$4+0.4),0) -> 0 | H34: =LN(B34) -> 7.278698 | I34: =IF(C34=1,LN(-LN(1-G34)),0) -> 0 | K34: =IF(C34=1,H34,NA()) -> #N/A | L34: =IF(C34=1,I34,NA()) -> #N/A | M34: =IF(C34=1,$P$12*H34+$P$13,"")
A35: 28 | B35: =SMALL(Datos!$C$5:$C$204,A35) -> 1472.7 | C35: =INDEX(Datos!$D$5:$D$204,MATCH(B35,Datos!$C$5:$C$204,0)) -> 1 | D35: =$B$4-A35+1 -> 173 | E35: =IF(C35=1,($B$4+1-F34)/(1+D35),0) -> 1.050245 | F35: =F34+E35 -> 19.307614 | G35: =IF(C35=1,(F35-0.3)/($B$4+0.4),0) -> 0.094848374 | H35: =LN(B35) -> 7.2948527 | I35: =IF(C35=1,LN(-LN(1-G35)),0) -> -2.3060631 | K35: =IF(C35=1,H35,NA()) -> 7.2948527 | L35: =IF(C35=1,I35,NA()) -> -2.3060631 | M35: =IF(C35=1,$P$12*H35+$P$13,"") -> -2.3801211
A36: 29 | B36: =SMALL(Datos!$C$5:$C$204,A36) -> 1472.8 | C36: =INDEX(Datos!$D$5:$D$204,MATCH(B36,Datos!$C$5:$C$204,0)) -> 0 | D36: =$B$4-A36+1 -> 172 | E36: =IF(C36=1,($B$4+1-F35)/(1+D36),0) -> 0 | F36: =F35+E36 -> 19.307614 | G36: =IF(C36=1,(F36-0.3)/($B$4+0.4),0) -> 0 | H36: =LN(B36) -> 7.2949206 | I36: =IF(C36=1,LN(-LN(1-G36)),0) -> 0 | K36: =IF(C36=1,H36,NA()) -> #N/A | L36: =IF(C36=1,I36,NA()) -> #N/A | M36: =IF(C36=1,$P$12*H36+$P$13,"")
A37: 30 | B37: =SMALL(Datos!$C$5:$C$204,A37) -> 1474.1 | C37: =INDEX(Datos!$D$5:$D$204,MATCH(B37,Datos!$C$5:$C$204,0)) -> 0 | D37: =$B$4-A37+1 -> 171 | E37: =IF(C37=1,($B$4+1-F36)/(1+D37),0) -> 0 | F37: =F36+E37 -> 19.307614 | G37: =IF(C37=1,(F37-0.3)/($B$4+0.4),0) -> 0 | H37: =LN(B37) -> 7.2958029 | I37: =IF(C37=1,LN(-LN(1-G37)),0) -> 0 | K37: =IF(C37=1,H37,NA()) -> #N/A | L37: =IF(C37=1,I37,NA()) -> #N/A | M37: =IF(C37=1,$P$12*H37+$P$13,"")
A38: 31 | B38: =SMALL(Datos!$C$5:$C$204,A38) -> 1528.3 | C38: =INDEX(Datos!$D$5:$D$204,MATCH(B38,Datos!$C$5:$C$204,0)) -> 0 | D38: =$B$4-A38+1 -> 170 | E38: =IF(C38=1,($B$4+1-F37)/(1+D38),0) -> 0 | F38: =F37+E38 -> 19.307614 | G38: =IF(C38=1,(F38-0.3)/($B$4+0.4),0) -> 0 | H38: =LN(B38) -> 7.3319113 | I38: =IF(C38=1,LN(-LN(1-G38)),0) -> 0 | K38: =IF(C38=1,H38,NA()) -> #N/A | L38: =IF(C38=1,I38,NA()) -> #N/A | M38: =IF(C38=1,$P$12*H38+$P$13,"")
... A207: 200 | B207: =SMALL(Datos!$C$5:$C$204,A207) -> 9165.7 | C207: =INDEX(Datos!$D$5:$D$204,MATCH(B207,Datos!$C$5:$C$204,0)) -> 0 | D207: =$B$4-A207+1 -> 1 | E207: =IF(C207=1,($B$4+1-F206)/(1+D207),0) -> 0 | F207: =F206+E207 -> 183.10953 | G207: =IF(C207=1,(F207-0.3)/($B$4+0.4),0) -> 0 | H207: =LN(B207) -> 9.1232235 | I207: =IF(C207=1,LN(-LN(1-G207)),0) -> 0 | K207: =IF(C207=1,H207,NA()) -> #N/A | L207: =IF(C207=1,I207,NA()) -> #N/A | M207: =IF(C207=1,$P$12*H207+$P$13,"")

Sheet Max_Verosimilitud
A1: ESTIMACION POR MAXIMA VEROSIMILITUD (MLE) Y PRUEBAS DE BONDAD DE AJUSTE
A2: Se resuelve la ecuacion de verosimilitud perfilada g(BETA)=0 por biseccion; ETA se obtiene en forma cerrada.
A4: Estadisticos suficientes | H4: Paso 2 — Estimadores de maxima verosimilitud | M4: Paso 4 — Pruebas de bondad de ajuste
A5: N | B5: =COUNT(Datos!$C$5:$C$204) -> 200 | H5: BETA (forma) | I5: =D56 -> 1.9476758 | M5: A. Razon de verosimilitud contra la exponencial (H0: BETA = 1)
A6: r (fallas) | B6: =SUM(Datos!$D$5:$D$204) -> 122 | H6: ETA (escala, h) | I6: =(SUMPRODUCT(Datos!$C$5:$C$204^$I$5)/$B$6)^(1/$I$5) -> 5099.776 | M6: ETA exponencial = SUM(t)/r | N6: =SUM(Datos!$C$5:$C$204)/$B$6 -> 5740.8893
A7: S1 = SUM(d*ln(t)) | B7: =SUMPRODUCT(Datos!$D$5:$D$204,Datos!$E$5:$E$204) -> 974.90977 | H7: log-verosimilitud l(BETA,ETA) | I7: =$B$6*LN($I$5)-$B$6*$I$5*LN($I$6)+($I$5-1)*$B$7-SUMPRODUCT((Datos!$C$5:$C$204/$I$6)^$I$5) -> -1145.2921 | M7: log-verosimilitud exponencial | N7: =-$B$6*LN($N$6)-SUM(Datos!$C$5:$C$204)/$N$6 -> -1177.9551
H8: Residual g(BETA) (debe ser ~0) | I8: =E56 -> 2.5757174e-14 | M8: Estadistico LR = 2*(lW - lE) | N8: =2*($I$7-$N$7) -> 65.325944
A9: Paso 1 — Solucion de g(BETA) = SUM(t^b*ln t)/SUM(t^b) - 1/b - S1/r = 0 (biseccion, 46 iteraciones) | M9: valor p (chi2 con 1 gl) | N9: =CHIDIST($N$8,1) -> 6.3480105e-16
A10: Iter k | B10: a (limite inf) | C10: b (limite sup) | D10: m = (a+b)/2 | E10: g(m) | F10: Amplitud (b-a) | H10: MTTF = ETA*GAMMA(1+1/BETA) (h) | I10: =$I$6*EXP(GAMMALN(1+1/$I$5)) -> 4522.1544 | M10: Decision | N10: =IF($N$9<0.05,"Se rechaza la exponencial: BETA es distinto de 1","No se rechaza la exponencial") -> Se rechaza la exponencial: BETA es distinto de 1
A11: 1 | B11: 0.1 | C11: 10 | D11: =(B11+C11)/2 -> 5.05 | E11: =SUMPRODUCT(Datos!$C$5:$C$204^D11,Datos!$E$5:$E$204)/SUMPRODUCT(Datos!$C$5:$C$204^D11)-1/D11-$B$7/$B$6 -> 0.64518968 | F11: =C11-B11 -> 9.9 | H11: Mediana (h) | I11: =$I$6*LN(2)^(1/$I$5) -> 4224.9904 | R11: Tabla de apoyo: ajuste vs. empirica
A12: 2 | B12: =IF(E11<0,D11,B11) -> 0.1 | C12: =IF(E11<0,C11,D11) -> 5.05 | D12: =(B12+C12)/2 -> 2.575 | E12: =SUMPRODUCT(Datos!$C$5:$C$204^D12,Datos!$E$5:$E$204)/SUMPRODUCT(Datos!$C$5:$C$204^D12)-1/D12-$B$7/$B$6 -> 0.22155954 | F12: =C12-B12 -> 4.95 | H12: Vida B10 (h) | I12: =$I$6*(-LN(0.9))^(1/$I$5) -> 1606.0616 | M12: B. Prueba Kolmogorov-Smirnov (Weibull MLE vs. empirica Kaplan-Meier) | R12: t(j) ordenado | S12: d | T12: F Weibull MLE | U12: F empirica (K-M) | V12: |diferencia| (fallas)
A13: 3 | B13: =IF(E12<0,D12,B12) -> 0.1 | C13: =IF(E12<0,C12,D12) -> 2.575 | D13: =(B13+C13)/2 -> 1.3375 | E13: =SUMPRODUCT(Datos!$C$5:$C$204^D13,Datos!$E$5:$E$204)/SUMPRODUCT(Datos!$C$5:$C$204^D13)-1/D13-$B$7/$B$6 -> -0.35259867 | F13: =C13-B13 -> 2.475 | M13: Estadistico D = max|F_W - F_KM| | N13: =MAX($V$13:$V$212) -> 0.049058692 | R13: =Metodo_Grafico!B8 -> 401.7 | S13: =Metodo_Grafico!C8 -> 1 | T13: =1-EXP(-((R13/$I$6)^$I$5)) -> 0.0070617291 | U13: =1-Kaplan_Meier!G8 -> 0.005 | V13: =IF(S13=1,ABS(T13-U13),0) -> 0.0020617291
A14: 4 | B14: =IF(E13<0,D13,B13) -> 1.3375 | C14: =IF(E13<0,C13,D13) -> 2.575 | D14: =(B14+C14)/2 -> 1.95625 | E14: =SUMPRODUCT(Datos!$C$5:$C$204^D14,Datos!$E$5:$E$204)/SUMPRODUCT(Datos!$C$5:$C$204^D14)-1/D14-$B$7/$B$6 -> 0.0037235281 | F14: =C14-B14 -> 1.2375 | H14: Paso 3 — Matriz de informacion observada (Hessiano numerico central) | M14: Valor critico aprox. 1.36/RAIZ(r) a=5% | N14: =1.36/SQRT($B$6) -> 0.12312861 | R14: =Metodo_Grafico!B9 -> 449.3 | S14: =Metodo_Grafico!C9 -> 1 | T14: =1-EXP(-((R14/$I$6)^$I$5)) -> 0.0087752783 | U14: =1-Kaplan_Meier!G9 -> 0.01 | V14: =IF(S14=1,ABS(T14-U14),0) -> 0.0012247217
A15: 5 | B15: =IF(E14<0,D14,B14) -> 1.3375 | C15: =IF(E14<0,C14,D14) -> 1.95625 | D15: =(B15+C15)/2 -> 1.646875 | E15: =SUMPRODUCT(Datos!$C$5:$C$204^D15,Datos!$E$5:$E$204)/SUMPRODUCT(Datos!$C$5:$C$204^D15)-1/D15-$B$7/$B$6 -> -0.14861488 | F15: =C15-B15 -> 0.61875 | H15: paso hb = 1% de BETA | I15: =0.01*$I$5 -> 0.019476758 | M15: Decision | N15: =IF($N$13<$N$14,"No se rechaza el ajuste Weibull","Se rechaza el ajuste Weibull") -> No se rechaza el ajuste Weibull | R15: =Metodo_Grafico!B10 -> 455.5 | S15: =Metodo_Grafico!C10 -> 1 | T15: =1-EXP(-((R15/$I$6)^$I$5)) -> 0.0090115955 | U15: =1-Kaplan_Meier!G10 -> 0.015 | V15: =IF(S15=1,ABS(T15-U15),0) -> 0.0059884045
A16: 6 | B16: =IF(E15<0,D15,B15) -> 1.646875 | C16: =IF(E15<0,C15,D15) -> 1.95625 | D16: =(B16+C16)/2 -> 1.8015625 | E16: =SUMPRODUCT(Datos!$C$5:$C$204^D16,Datos!$E$5:$E$204)/SUMPRODUCT(Datos!$C$5:$C$204^D16)-1/D16-$B$7/$B$6 -> -0.067491551 | F16: =C16-B16 -> 0.309375 | H16: paso he = 1% de ETA | I16: =0.01*$I$6 -> 50.99776 | R16: =Metodo_Grafico!B11 -> 528.3 | S16: =Metodo_Grafico!C11 -> 1 | T16: =1-EXP(-((R16/$I$6)^$I$5)) -> 0.012010468 | U16: =1-Kaplan_Meier!G11 -> 0.02 | V16: =IF(S16=1,ABS(T16-U16),0) -> 0.0079895322
A17: 7 | B17: =IF(E16<0,D16,B16) -> 1.8015625 | C17: =IF(E16<0,C16,D16) -> 1.95625 | D17: =(B17+C17)/2 -> 1.8789062 | E17: =SUMPRODUCT(Datos!$C$5:$C$204^D17,Datos!$E$5:$E$204)/SUMPRODUCT(Datos!$C$5:$C$204^D17)-1/D17-$B$7/$B$6 -> -0.030780898 | F17: =C17-B17 -> 0.1546875 | M17: C. Criterios de informacion (menor es mejor) | R17: =Metodo_Grafico!B12 -> 602 | S17: =Metodo_Grafico!C12 -> 1 | T17: =1-EXP(-((R17/$I$6)^$I$5)) -> 0.015462008 | U17: =1-Kaplan_Meier!G12 -> 0.025 | V17: =IF(S17=1,ABS(T17-U17),0) -> 0.0095379921
A18: 8 | B18: =IF(E17<0,D17,B17) -> 1.8789062 | C18: =IF(E17<0,C17,D17) -> 1.95625 | D18: =(B18+C18)/2 -> 1.9175781 | E18: =SUMPRODUCT(Datos!$C$5:$C$204^D18,Datos!$E$5:$E$204)/SUMPRODUCT(Datos!$C$5:$C$204^D18)-1/D18-$B$7/$B$6 -> -0.013267544 | F18: =C18-B18 -> 0.07734375 | H18: l(BETA, ETA) en malla 3x3 | M18: AIC Weibull (k=2) | N18: =-2*$I$7+4 -> 2294.5842 | R18: =Metodo_Grafico!B13 -> 707.6 | S18: =Metodo_Grafico!C13 -> 1 | T18: =1-EXP(-((R18/$I$6)^$I$5)) -> 0.021121649 | U18: =1-Kaplan_Meier!G13 -> 0.03 | V18: =IF(S18=1,ABS(T18-U18),0) -> 0.0088783507
A19: 9 | B19: =IF(E18<0,D18,B18) -> 1.9175781 | C19: =IF(E18<0,C18,D18) -> 1.95625 | D19: =(B19+C19)/2 -> 1.9369141 | E19: =SUMPRODUCT(Datos!$C$5:$C$204^D19,Datos!$E$5:$E$204)/SUMPRODUCT(Datos!$C$5:$C$204^D19)-1/D19-$B$7/$B$6 -> -0.0047084303 | F19: =C19-B19 -> 0.038671875 | I19: =$I$6-$I$16 -> 5048.7782 | J19: =$I$6 -> 5099.776 | K19: =$I$6+$I$16 -> 5150.7737 | M19: AIC Exponencial (k=1) | N19: =-2*$N$7+2 -> 2357.9101 | R19: =Metodo_Grafico!B14 -> 820.7 | S19: =Metodo_Grafico!C14 -> 1 | T19: =1-EXP(-((R19/$I$6)^$I$5)) -> 0.028093502 | U19: =1-Kaplan_Meier!G14 -> 0.035 | V19: =IF(S19=1,ABS(T19-U19),0) -> 0.0069064984
A20: 10 | B20: =IF(E19<0,D19,B19) -> 1.9369141 | C20: =IF(E19<0,C19,D19) -> 1.95625 | D20: =(B20+C20)/2 -> 1.946582 | E20: =SUMPRODUCT(Datos!$C$5:$C$204^D20,Datos!$E$5:$E$204)/SUMPRODUCT(Datos!$C$5:$C$204^D20)-1/D20-$B$7/$B$6 -> -0.00047676313 | F20: =C20-B20 -> 0.019335937 | H20: =$I$5-$I$15 -> 1.9281991 | I20: =$B$6*LN($H20)-$B$6*$H20*LN(I$19)+($H20-1)*$B$7-SUMPRODUCT((Datos!$C$5:$C$204/I$19)^$H20) -> -1145.3269 | J20: =$B$6*LN($H20)-$B$6*$H20*LN(J$19)+($H20-1)*$B$7-SUMPRODUCT((Datos!$C$5:$C$204/J$19)^$H20) -> -1145.3023 | K20: =$B$6*LN($H20)-$B$6*$H20*LN(K$19)+($H20-1)*$B$7-SUMPRODUCT((Datos!$C$5:$C$204/K$19)^$H20) -> -1145.323 | M20: BIC Weibull | N20: =-2*$I$7+2*LN($B$5) -> 2301.1808 | R20: =Metodo_Grafico!B15 -> 871.6 | S20: =Metodo_Grafico!C15 -> 1 | T20: =1-EXP(-((R20/$I$6)^$I$5)) -> 0.031531059 | U20: =1-Kaplan_Meier!G15 -> 0.04 | V20: =IF(S20=1,ABS(T20-U20),0) -> 0.0084689408
A21: 11 | B21: =IF(E20<0,D20,B20) -> 1.946582 | C21: =IF(E20<0,C20,D20) -> 1.95625 | D21: =(B21+C21)/2 -> 1.951416 | E21: =SUMPRODUCT(Datos!$C$5:$C$204^D21,Datos!$E$5:$E$204)/SUMPRODUCT(Datos!$C$5:$C$204^D21)-1/D21-$B$7/$B$6 -> 0.0016272791 | F21: =C21-B21 -> 0.0096679688 | H21: =$I$5 -> 1.9476758 | I21: =$B$6*LN($H21)-$B$6*$H21*LN(I$19)+($H21-1)*$B$7-SUMPRODUCT((Datos!$C$5:$C$204/I$19)^$H21) -> -1145.3156 | J21: =$B$6*LN($H21)-$B$6*$H21*LN(J$19)+($H21-1)*$B$7-SUMPRODUCT((Datos!$C$5:$C$204/J$19)^$H21) -> -1145.2921 | K21: =$B$6*LN($H21)-$B$6*$H21*LN(K$19)+($H21-1)*$B$7-SUMPRODUCT((Datos!$C$5:$C$204/K$19)^$H21) -> -1145.3149 | M21: Modelo preferido | N21: =IF($N$18<$N$19,"Weibull de 2 parametros","Exponencial") -> Weibull de 2 parametros | R21: =Metodo_Grafico!B16 -> 873.6 | S21: =Metodo_Grafico!C16 -> 1 | T21: =1-EXP(-((R21/$I$6)^$I$5)) -> 0.031669873 | U21: =1-Kaplan_Meier!G16 -> 0.045 | V21: =IF(S21=1,ABS(T21-U21),0) -> 0.013330127
A22: 12 | B22: =IF(E21<0,D21,B21) -> 1.946582 | C22: =IF(E21<0,C21,D21) -> 1.951416 | D22: =(B22+C22)/2 -> 1.948999 | E22: =SUMPRODUCT(Datos!$C$5:$C$204^D22,Datos!$E$5:$E$204)/SUMPRODUCT(Datos!$C$5:$C$204^D22)-1/D22-$B$7/$B$6 -> 0.00057623529 | F22: =C22-B22 -> 0.0048339844 | H22: =$I$5+$I$15 -> 1.9671526 | I22: =$B$6*LN($H22)-$B$6*$H22*LN(I$19)+($H22-1)*$B$7-SUMPRODUCT((Datos!$C$5:$C$204/I$19)^$H22) -> -1145.3247 | J22: =$B$6*LN($H22)-$B$6*$H22*LN(J$19)+($H22-1)*$B$7-SUMPRODUCT((Datos!$C$5:$C$204/J$19)^$H22) -> -1145.3022 | K22: =$B$6*LN($H22)-$B$6*$H22*LN(K$19)+($H22-1)*$B$7-SUMPRODUCT((Datos!$C$5:$C$204/K$19)^$H22) -> -1145.3268 | R22: =Metodo_Grafico!B17 -> 941.7 | S22: =Metodo_Grafico!C17 -> 1 | T22: =1-EXP(-((R22/$I$6)^$I$5)) -> 0.036563407 | U22: =1-Kaplan_Meier!G17 -> 0.05 | V22: =IF(S22=1,ABS(T22-U22),0) -> 0.013436593
A23: 13 | B23: =IF(E22<0,D22,B22) -> 1.946582 | C23: =IF(E22<0,C22,D22) -> 1.948999 | D23: =(B23+C23)/2 -> 1.9477905 | E23: =SUMPRODUCT(Datos!$C$5:$C$204^D23,Datos!$E$5:$E$204)/SUMPRODUCT(Datos!$C$5:$C$204^D23)-1/D23-$B$7/$B$6 -> 4.9980804e-05 | F23: =C23-B23 -> 0.0024169922 | M23: D. Correlacion del papel de probabilidad | R23: =Metodo_Grafico!B18 -> 960.8 | S23: =Metodo_Grafico!C18 -> 0 | T23: =1-EXP(-((R23/$I$6)^$I$5)) -> 0.037993619 | U23: =1-Kaplan_Meier!G18 -> 0.05 | V23: =IF(S23=1,ABS(T23-U23),0) -> 0
A24: 14 | B24: =IF(E23<0,D23,B23) -> 1.946582 | C24: =IF(E23<0,C23,D23) -> 1.9477905 | D24: =(B24+C24)/2 -> 1.9471863 | E24: =SUMPRODUCT(Datos!$C$5:$C$204^D24,Datos!$E$5:$E$204)/SUMPRODUCT(Datos!$C$5:$C$204^D24)-1/D24-$B$7/$B$6 -> -0.00021332993 | F24: =C24-B24 -> 0.0012084961 | H24: d2l/dBETA2 | I24: =(J22-2*J21+J20)/$I$15^2 -> -53.286407 | M24: R cuadrado del grafico Weibull | N24: =Metodo_Grafico!$P$19 -> 0.98984743 | R24: =Metodo_Grafico!B19 -> 1024.2 | S24: =Metodo_Grafico!C19 -> 0 | T24: =1-EXP(-((R24/$I$6)^$I$5)) -> 0.04291954 | U24: =1-Kaplan_Meier!G19 -> 0.05 | V24: =IF(S24=1,ABS(T24-U24),0) -> 0
A25: 15 | B25: =IF(E24<0,D24,B24) -> 1.9471863 | C25: =IF(E24<0,C24,D24) -> 1.9477905 | D25: =(B25+C25)/2 -> 1.9474884 | E25: =SUMPRODUCT(Datos!$C$5:$C$204^D25,Datos!$E$5:$E$204)/SUMPRODUCT(Datos!$C$5:$C$204^D25)-1/D25-$B$7/$B$6 -> -8.1659263e-05 | F25: =C25-B25 -> 0.00060424805 | H25: d2l/dETA2 | I25: =(K21-2*J21+I21)/$I$16^2 -> -1.779864e-05 | M25: Lectura | N25: =IF($N$24>0.95,"Linealidad alta: el supuesto Weibull es razonable","Revisar el supuesto Weibull") -> Linealidad alta: el supuesto Weibull es razonable | R25: =Metodo_Grafico!B20 -> 1073.5 | S25: =Metodo_Grafico!C20 -> 0 | T25: =1-EXP(-((R25/$I$6)^$I$5)) -> 0.046936952 | U25: =1-Kaplan_Meier!G20 -> 0.05 | V25: =IF(S25=1,ABS(T25-U25),0) -> 0
A26: 16 | B26: =IF(E25<0,D25,B25) -> 1.9474884 | C26: =IF(E25<0,C25,D25) -> 1.9477905 | D26: =(B26+C26)/2 -> 1.9476395 | E26: =SUMPRODUCT(Datos!$C$5:$C$204^D26,Datos!$E$5:$E$204)/SUMPRODUCT(Datos!$C$5:$C$204^D26)-1/D26-$B$7/$B$6 -> -1.5835405e-05 | F26: =C26-B26 -> 0.00030212402 | H26: d2l/dBETAdETA | I26: =(K22-I22-K20+I20)/(4*$I$15*$I$16) -> -0.0015027729 | R26: =Metodo_Grafico!B21 -> 1077.1 | S26: =Metodo_Grafico!C21 -> 1 | T26: =1-EXP(-((R26/$I$6)^$I$5)) -> 0.047236642 | U26: =1-Kaplan_Meier!G21 -> 0.055080214 | V26: =IF(S26=1,ABS(T26-U26),0) -> 0.0078435722
A27: 17 | B27: =IF(E26<0,D26,B26) -> 1.9476395 | C27: =IF(E26<0,C26,D26) -> 1.9477905 | D27: =(B27+C27)/2 -> 1.947715 | E27: =SUMPRODUCT(Datos!$C$5:$C$204^D27,Datos!$E$5:$E$204)/SUMPRODUCT(Datos!$C$5:$C$204^D27)-1/D27-$B$7/$B$6 -> 1.7073655e-05 | F27: =C27-B27 -> 0.00015106201 | H27: Determinante de I | I27: =(-$I$24)*(-$I$25)-(-$I$26)^2 -> 0.00094616722 | M27: Advertencia metodologica | R27: =Metodo_Grafico!B22 -> 1099.2 | S27: =Metodo_Grafico!C22 -> 1 | T27: =1-EXP(-((R27/$I$6)^$I$5)) -> 0.049095125 | U27: =1-Kaplan_Meier!G22 -> 0.060160428 | V27: =IF(S27=1,ABS(T27-U27),0) -> 0.011065303
A28: 18 | B28: =IF(E27<0,D27,B27) -> 1.9476395 | C28: =IF(E27<0,C27,D27) -> 1.947715 | D28: =(B28+C28)/2 -> 1.9476772 | E28: =SUMPRODUCT(Datos!$C$5:$C$204^D28,Datos!$E$5:$E$204)/SUMPRODUCT(Datos!$C$5:$C$204^D28)-1/D28-$B$7/$B$6 -> 6.1936423e-07 | F28: =C28-B28 -> 7.5531006e-05 | H28: error estandar de BETA | I28: =SQRT(-$I$25/$I$27) -> 0.13715431 | M28: El valor critico de Kolmogorov-Smirnov mostrado supone parametros conocidos. Como aqui fueron estimados de la misma muestra, la prueba es conservadora (tiende a no rechazar). Para una decision formal se requiere el valor critico de Lilliefors o una calibracion por bootstrap parametrico. Se reporta como evidencia descriptiva y se complementa con la prueba LR y los criterios AIC/BIC. | R28: =Metodo_Grafico!B23 -> 1133.3 | S28: =Metodo_Grafico!C23 -> 0 | T28: =1-EXP(-((R28/$I$6)^$I$5)) -> 0.052025475 | U28: =1-Kaplan_Meier!G23 -> 0.060160428 | V28: =IF(S28=1,ABS(T28-U28),0) -> 0
A29: 19 | B29: =IF(E28<0,D28,B28) -> 1.9476395 | C29: =IF(E28<0,C28,D28) -> 1.9476772 | D29: =(B29+C29)/2 -> 1.9476583 | E29: =SUMPRODUCT(Datos!$C$5:$C$204^D29,Datos!$E$5:$E$204)/SUMPRODUCT(Datos!$C$5:$C$204^D29)-1/D29-$B$7/$B$6 -> -7.6079607e-06 | F29: =C29-B29 -> 3.7765503e-05 | H29: error estandar de ETA | I29: =SQRT(-$I$24/$I$27) -> 237.3145 | R29: =Metodo_Grafico!B24 -> 1161.6 | S29: =Metodo_Grafico!C24 -> 1 | T29: =1-EXP(-((R29/$I$6)^$I$5)) -> 0.054514656 | U29: =1-Kaplan_Meier!G24 -> 0.065268252 | V29: =IF(S29=1,ABS(T29-U29),0) -> 0.010753596
A30: 20 | B30: =IF(E29<0,D29,B29) -> 1.9476583 | C30: =IF(E29<0,C29,D29) -> 1.9476772 | D30: =(B30+C30)/2 -> 1.9476678 | E30: =SUMPRODUCT(Datos!$C$5:$C$204^D30,Datos!$E$5:$E$204)/SUMPRODUCT(Datos!$C$5:$C$204^D30)-1/D30-$B$7/$B$6 -> -3.4942833e-06 | F30: =C30-B30 -> 1.8882751e-05 | H30: IC 95% BETA inferior | I30: =$I$5*EXP(-1.959964*$I$28/$I$5) -> 1.6965845 | R30: =Metodo_Grafico!B25 -> 1196.6 | S30: =Metodo_Grafico!C25 -> 0 | T30: =1-EXP(-((R30/$I$6)^$I$5)) -> 0.057664152 | U30: =1-Kaplan_Meier!G25 -> 0.065268252 | V30: =IF(S30=1,ABS(T30-U30),0) -> 0
A31: 21 | B31: =IF(E30<0,D30,B30) -> 1.9476678 | C31: =IF(E30<0,C30,D30) -> 1.9476772 | D31: =(B31+C31)/2 -> 1.9476725 | E31: =SUMPRODUCT(Datos!$C$5:$C$204^D31,Datos!$E$5:$E$204)/SUMPRODUCT(Datos!$C$5:$C$204^D31)-1/D31-$B$7/$B$6 -> -1.4374558e-06 | F31: =C31-B31 -> 9.4413757e-06 | H31: IC 95% BETA superior | I31: =$I$5*EXP(1.959964*$I$28/$I$5) -> 2.2359281 | R31: =Metodo_Grafico!B26 -> 1230.9 | S31: =Metodo_Grafico!C26 -> 1 | T31: =1-EXP(-((R31/$I$6)^$I$5)) -> 0.060825943 | U31: =1-Kaplan_Meier!G26 -> 0.07040414 | V31: =IF(S31=1,ABS(T31-U31),0) -> 0.0095781968
A32: 22 | B32: =IF(E31<0,D31,B31) -> 1.9476725 | C32: =IF(E31<0,C31,D31) -> 1.9476772 | D32: =(B32+C32)/2 -> 1.9476749 | E32: =SUMPRODUCT(Datos!$C$5:$C$204^D32,Datos!$E$5:$E$204)/SUMPRODUCT(Datos!$C$5:$C$204^D32)-1/D32-$B$7/$B$6 -> -4.0904484e-07 | F32: =C32-B32 -> 4.7206879e-06 | H32: IC 95% ETA inferior | I32: =$I$6*EXP(-1.959964*$I$29/$I$6) -> 4655.2288 | R32: =Metodo_Grafico!B27 -> 1240.7 | S32: =Metodo_Grafico!C27 -> 0 | T32: =1-EXP(-((R32/$I$6)^$I$5)) -> 0.061742868 | U32: =1-Kaplan_Meier!G27 -> 0.07040414 | V32: =IF(S32=1,ABS(T32-U32),0) -> 0
A33: 23 | B33: =IF(E32<0,D32,B32) -> 1.9476749 | C33: =IF(E32<0,C32,D32) -> 1.9476772 | D33: =(B33+C33)/2 -> 1.9476761 | E33: =SUMPRODUCT(Datos!$C$5:$C$204^D33,Datos!$E$5:$E$204)/SUMPRODUCT(Datos!$C$5:$C$204^D33)-1/D33-$B$7/$B$6 -> 1.0515993e-07 | F33: =C33-B33 -> 2.3603439e-06 | H33: IC 95% ETA superior | I33: =$I$6*EXP(1.959964*$I$29/$I$6) -> 5586.7748 | R33: =Metodo_Grafico!B28 -> 1265.2 | S33: =Metodo_Grafico!C28 -> 0 | T33: =1-EXP(-((R33/$I$6)^$I$5)) -> 0.064061311 | U33: =1-Kaplan_Meier!G28 -> 0.07040414 | V33: =IF(S33=1,ABS(T33-U33),0) -> 0
A34: 24 | B34: =IF(E33<0,D33,B33) -> 1.9476749 | C34: =IF(E33<0,C33,D33) -> 1.9476761 | D34: =(B34+C34)/2 -> 1.9476755 | E34: =SUMPRODUCT(Datos!$C$5:$C$204^D34,Datos!$E$5:$E$204)/SUMPRODUCT(Datos!$C$5:$C$204^D34)-1/D34-$B$7/$B$6 -> -1.519424e-07 | F34: =C34-B34 -> 1.180172e-06 | R34: =Metodo_Grafico!B29 -> 1308.3 | S34: =Metodo_Grafico!C29 -> 0 | T34: =1-EXP(-((R34/$I$6)^$I$5)) -> 0.068229585 | U34: =1-Kaplan_Meier!G29 -> 0.07040414 | V34: =IF(S34=1,ABS(T34-U34),0) -> 0
A35: 25 | B35: =IF(E34<0,D34,B34) -> 1.9476755 | C35: =IF(E34<0,C34,D34) -> 1.9476761 | D35: =(B35+C35)/2 -> 1.9476758 | E35: =SUMPRODUCT(Datos!$C$5:$C$204^D35,Datos!$E$5:$E$204)/SUMPRODUCT(Datos!$C$5:$C$204^D35)-1/D35-$B$7/$B$6 -> -2.339122e-08 | F35: =C35-B35 -> 5.9008598e-07 | R35: =Metodo_Grafico!B30 -> 1360.3 | S35: =Metodo_Grafico!C30 -> 1 | T35: =1-EXP(-((R35/$I$6)^$I$5)) -> 0.073408483 | U35: =1-Kaplan_Meier!G30 -> 0.075626589 | V35: =IF(S35=1,ABS(T35-U35),0) -> 0.0022181056
A36: 26 | B36: =IF(E35<0,D35,B35) -> 1.9476758 | C36: =IF(E35<0,C35,D35) -> 1.9476761 | D36: =(B36+C36)/2 -> 1.9476759 | E36: =SUMPRODUCT(Datos!$C$5:$C$204^D36,Datos!$E$5:$E$204)/SUMPRODUCT(Datos!$C$5:$C$204^D36)-1/D36-$B$7/$B$6 -> 4.0884352e-08 | F36: =C36-B36 -> 2.9504299e-07 | R36: =Metodo_Grafico!B31 -> 1392.9 | S36: =Metodo_Grafico!C31 -> 1 | T36: =1-EXP(-((R36/$I$6)^$I$5)) -> 0.076737419 | U36: =1-Kaplan_Meier!G31 -> 0.080849038 | V36: =IF(S36=1,ABS(T36-U36),0) -> 0.0041116187
A37: 27 | B37: =IF(E36<0,D36,B36) -> 1.9476758 | C37: =IF(E36<0,C36,D36) -> 1.9476759 | D37: =(B37+C37)/2 -> 1.9476758 | E37: =SUMPRODUCT(Datos!$C$5:$C$204^D37,Datos!$E$5:$E$204)/SUMPRODUCT(Datos!$C$5:$C$204^D37)-1/D37-$B$7/$B$6 -> 8.7465635e-09 | F37: =C37-B37 -> 1.475215e-07 | R37: =Metodo_Grafico!B32 -> 1441.9 | S37: =Metodo_Grafico!C32 -> 1 | T37: =1-EXP(-((R37/$I$6)^$I$5)) -> 0.081857954 | U37: =1-Kaplan_Meier!G32 -> 0.086071486 | V37: =IF(S37=1,ABS(T37-U37),0) -> 0.0042135323
A38: 28 | B38: =IF(E37<0,D37,B37) -> 1.9476758 | C38: =IF(E37<0,C37,D37) -> 1.9476758 | D38: =(B38+C38)/2 -> 1.9476758 | E38: =SUMPRODUCT(Datos!$C$5:$C$204^D38,Datos!$E$5:$E$204)/SUMPRODUCT(Datos!$C$5:$C$204^D38)-1/D38-$B$7/$B$6 -> -7.322333e-09 | F38: =C38-B38 -> 7.3760748e-08 | R38: =Metodo_Grafico!B33 -> 1442.2 | S38: =Metodo_Grafico!C33 -> 1 | T38: =1-EXP(-((R38/$I$6)^$I$5)) -> 0.081889732 | U38: =1-Kaplan_Meier!G33 -> 0.091293935 | V38: =IF(S38=1,ABS(T38-U38),0) -> 0.0094042033
A39: 29 | B39: =IF(E38<0,D38,B38) -> 1.9476758 | C39: =IF(E38<0,C38,D38) -> 1.9476758 | D39: =(B39+C39)/2 -> 1.9476758 | E39: =SUMPRODUCT(Datos!$C$5:$C$204^D39,Datos!$E$5:$E$204)/SUMPRODUCT(Datos!$C$5:$C$204^D39)-1/D39-$B$7/$B$6 -> 7.1212192e-10 | F39: =C39-B39 -> 3.6880374e-08 | R39: =Metodo_Grafico!B34 -> 1449.1 | S39: =Metodo_Grafico!C34 -> 0 | T39: =1-EXP(-((R39/$I$6)^$I$5)) -> 0.082622042 | U39: =1-Kaplan_Meier!G34 -> 0.091293935 | V39: =IF(S39=1,ABS(T39-U39),0) -> 0
A40: 30 | B40: =IF(E39<0,D39,B39) -> 1.9476758 | C40: =IF(E39<0,C39,D39) -> 1.9476758 | D40: =(B40+C40)/2 -> 1.9476758 | E40: =SUMPRODUCT(Datos!$C$5:$C$204^D40,Datos!$E$5:$E$204)/SUMPRODUCT(Datos!$C$5:$C$204^D40)-1/D40-$B$7/$B$6 -> -3.3051073e-09 | F40: =C40-B40 -> 1.8440187e-08 | R40: =Metodo_Grafico!B35 -> 1472.7 | S40: =Metodo_Grafico!C35 -> 1 | T40: =1-EXP(-((R40/$I$6)^$I$5)) -> 0.085147296 | U40: =1-Kaplan_Meier!G35 -> 0.096546571 | V40: =IF(S40=1,ABS(T40-U40),0) -> 0.011399276
A41: 31 | B41: =IF(E40<0,D40,B40) -> 1.9476758 | C41: =IF(E40<0,C40,D40) -> 1.9476758 | D41: =(B41+C41)/2 -> 1.9476758 | E41: =SUMPRODUCT(Datos!$C$5:$C$204^D41,Datos!$E$5:$E$204)/SUMPRODUCT(Datos!$C$5:$C$204^D41)-1/D41-$B$7/$B$6 -> -1.2964883e-09 | F41: =C41-B41 -> 9.2200936e-09 | R41: =Metodo_Grafico!B36 -> 1472.8 | S41: =Metodo_Grafico!C36 -> 0 | T41: =1-EXP(-((R41/$I$6)^$I$5)) -> 0.085158063 | U41: =1-Kaplan_Meier!G36 -> 0.096546571 | V41: =IF(S41=1,ABS(T41-U41),0) -> 0
...

Sheet Kaplan_Meier
A1: ESTIMADOR NO PARAMETRICO DE KAPLAN-MEIER CON INTERVALOS DE CONFIANZA
A2: Producto-limite sobre los tiempos de falla. Varianza por la formula de Greenwood e IC 95% con transformacion log-log.
A4: N = | B4: =Metodo_Grafico!$B$4 -> 200 | N4: Resultados Kaplan-Meier
A5: z (95%) = | B5: 1.959964 | N5: Mediana de supervivencia (h) | O5: =INDEX($B$8:$B$207,COUNTIF($G$8:$G$207,">0.5")+1) -> 4118.5
N6: S(t) en el ultimo tiempo observado | O6: =G207 -> 0.075302996
A7: j | B7: t(j) (h) | C7: d (1=falla) | D7: n(j) en riesgo | E7: d(j) fallas | F7: Factor 1-d/n | G7: S(t) Kaplan-Meier | H7: Term. Greenwood | I7: Suma Greenwood | J7: e.e. Greenwood | K7: IC 95% inferior | L7: IC 95% superior | N7: Ultimo tiempo observado (h) | O7: =B207 -> 9165.7
A8: 1 | B8: =Metodo_Grafico!B8 -> 401.7 | C8: =Metodo_Grafico!C8 -> 1 | D8: =$B$4-A8+1 -> 200 | E8: =C8 -> 1 | F8: =IF(C8=1,(D8-E8)/D8,1) -> 0.995 | G8: =1*F8 -> 0.995 | H8: =IF(AND(C8=1,D8-E8>0),E8/(D8*(D8-E8)),0) -> 2.5125628e-05 | I8: =0+H8 -> 2.5125628e-05 | J8: =G8*SQRT(I8) -> 0.0049874843 | K8: =IF(OR(G8>=1,G8<=0),"",G8^EXP($B$5*SQRT(I8)/ABS(LN(G8)))) -> 0.96504122 | L8: =IF(OR(G8>=1,G8<=0),"",G8^EXP(-$B$5*SQRT(I8)/ABS(LN(G8)))) -> 0.99929417 | N8: Ultima observacion es censurada? | O8: =IF(C207=0,"Si - la curva no llega a cero","No") -> Si - la curva no llega a cero
A9: 2 | B9: =Metodo_Grafico!B9 -> 449.3 | C9: =Metodo_Grafico!C9 -> 1 | D9: =$B$4-A9+1 -> 199 | E9: =C9 -> 1 | F9: =IF(C9=1,(D9-E9)/D9,1) -> 0.99497487 | G9: =G8*F9 -> 0.99 | H9: =IF(AND(C9=1,D9-E9>0),E9/(D9*(D9-E9)),0) -> 2.5379422e-05 | I9: =I8+H9 -> 5.0505051e-05 | J9: =G9*SQRT(I9) -> 0.0070356236 | K9: =IF(OR(G9>=1,G9<=0),"",G9^EXP($B$5*SQRT(I9)/ABS(LN(G9)))) -> 0.96061086 | L9: =IF(OR(G9>=1,G9<=0),"",G9^EXP(-$B$5*SQRT(I9)/ABS(LN(G9)))) -> 0.99748961
A10: 3 | B10: =Metodo_Grafico!B10 -> 455.5 | C10: =Metodo_Grafico!C10 -> 1 | D10: =$B$4-A10+1 -> 198 | E10: =C10 -> 1 | F10: =IF(C10=1,(D10-E10)/D10,1) -> 0.99494949 | G10: =G9*F10 -> 0.985 | H10: =IF(AND(C10=1,D10-E10>0),E10/(D10*(D10-E10)),0) -> 2.5637081e-05 | I10: =I9+H10 -> 7.6142132e-05 | J10: =G10*SQRT(I10) -> 0.0085950567 | K10: =IF(OR(G10>=1,G10<=0),"",G10^EXP($B$5*SQRT(I10)/ABS(LN(G10)))) -> 0.95421966 | L10: =IF(OR(G10>=1,G10<=0),"",G10^EXP(-$B$5*SQRT(I10)/ABS(LN(G10)))) -> 0.99513744 | N10: Confiabilidad estimada en tiempos clave | P10: IC inf. | Q10: IC sup.
A11: 4 | B11: =Metodo_Grafico!B11 -> 528.3 | C11: =Metodo_Grafico!C11 -> 1 | D11: =$B$4-A11+1 -> 197 | E11: =C11 -> 1 | F11: =IF(C11=1,(D11-E11)/D11,1) -> 0.99492386 | G11: =G10*F11 -> 0.98 | H11: =IF(AND(C11=1,D11-E11>0),E11/(D11*(D11-E11)),0) -> 2.5898684e-05 | I11: =I10+H11 -> 0.00010204082 | J11: =G11*SQRT(I11) -> 0.0098994949 | K11: =IF(OR(G11>=1,G11<=0),"",G11^EXP($B$5*SQRT(I11)/ABS(LN(G11)))) -> 0.94759398 | L11: =IF(OR(G11>=1,G11<=0),"",G11^EXP(-$B$5*SQRT(I11)/ABS(LN(G11)))) -> 0.99244636 | N11: S(1000 h) | O11: =IFERROR(LOOKUP(1000,$B$8:$B$207,$G$8:$G$207),1) -> 0.95 | P11: =IFERROR(LOOKUP(1000,$B$8:$B$207,$K$8:$K$207),"") -> 0.90906609 | Q11: =IFERROR(LOOKUP(1000,$B$8:$B$207,$L$8:$L$207),"") -> 0.97278059
A12: 5 | B12: =Metodo_Grafico!B12 -> 602 | C12: =Metodo_Grafico!C12 -> 1 | D12: =$B$4-A12+1 -> 196 | E12: =C12 -> 1 | F12: =IF(C12=1,(D12-E12)/D12,1) -> 0.99489796 | G12: =G11*F12 -> 0.975 | H12: =IF(AND(C12=1,D12-E12>0),E12/(D12*(D12-E12)),0) -> 2.6164312e-05 | I12: =I11+H12 -> 0.00012820513 | J12: =G12*SQRT(I12) -> 0.011039701 | K12: =IF(OR(G12>=1,G12<=0),"",G12^EXP($B$5*SQRT(I12)/ABS(LN(G12)))) -> 0.94098486 | L12: =IF(OR(G12>=1,G12<=0),"",G12^EXP(-$B$5*SQRT(I12)/ABS(LN(G12)))) -> 0.9895176 | N12: S(2000 h) | O12: =IFERROR(LOOKUP(2000,$B$8:$B$207,$G$8:$G$207),1) -> 0.87538059 | P12: =IFERROR(LOOKUP(2000,$B$8:$B$207,$K$8:$K$207),"") -> 0.81967729 | Q12: =IFERROR(LOOKUP(2000,$B$8:$B$207,$L$8:$L$207),"") -> 0.91476497
A13: 6 | B13: =Metodo_Grafico!B13 -> 707.6 | C13: =Metodo_Grafico!C13 -> 1 | D13: =$B$4-A13+1 -> 195 | E13: =C13 -> 1 | F13: =IF(C13=1,(D13-E13)/D13,1) -> 0.99487179 | G13: =G12*F13 -> 0.97 | H13: =IF(AND(C13=1,D13-E13>0),E13/(D13*(D13-E13)),0) -> 2.6434047e-05 | I13: =I12+H13 -> 0.00015463918 | J13: =G13*SQRT(I13) -> 0.012062338 | K13: =IF(OR(G13>=1,G13<=0),"",G13^EXP($B$5*SQRT(I13)/ABS(LN(G13)))) -> 0.93444677 | L13: =IF(OR(G13>=1,G13<=0),"",G13^EXP(-$B$5*SQRT(I13)/ABS(LN(G13)))) -> 0.98640949 | N13: S(3000 h) | O13: =IFERROR(LOOKUP(3000,$B$8:$B$207,$G$8:$G$207),1) -> 0.72015613 | P13: =IFERROR(LOOKUP(3000,$B$8:$B$207,$K$8:$K$207),"") -> 0.64729092 | Q13: =IFERROR(LOOKUP(3000,$B$8:$B$207,$L$8:$L$207),"") -> 0.78053476
A14: 7 | B14: =Metodo_Grafico!B14 -> 820.7 | C14: =Metodo_Grafico!C14 -> 1 | D14: =$B$4-A14+1 -> 194 | E14: =C14 -> 1 | F14: =IF(C14=1,(D14-E14)/D14,1) -> 0.99484536 | G14: =G13*F14 -> 0.965 | H14: =IF(AND(C14=1,D14-E14>0),E14/(D14*(D14-E14)),0) -> 2.6707975e-05 | I14: =I13+H14 -> 0.00018134715 | J14: =G14*SQRT(I14) -> 0.012995191 | K14: =IF(OR(G14>=1,G14<=0),"",G14^EXP($B$5*SQRT(I14)/ABS(LN(G14)))) -> 0.92798964 | L14: =IF(OR(G14>=1,G14<=0),"",G14^EXP(-$B$5*SQRT(I14)/ABS(LN(G14)))) -> 0.9831594 | N14: S(4000 h) | O14: =IFERROR(LOOKUP(4000,$B$8:$B$207,$G$8:$G$207),1) -> 0.51588682 | P14: =IFERROR(LOOKUP(4000,$B$8:$B$207,$K$8:$K$207),"") -> 0.43417655 | Q14: =IFERROR(LOOKUP(4000,$B$8:$B$207,$L$8:$L$207),"") -> 0.5915132
A15: 8 | B15: =Metodo_Grafico!B15 -> 871.6 | C15: =Metodo_Grafico!C15 -> 1 | D15: =$B$4-A15+1 -> 193 | E15: =C15 -> 1 | F15: =IF(C15=1,(D15-E15)/D15,1) -> 0.99481865 | G15: =G14*F15 -> 0.96 | H15: =IF(AND(C15=1,D15-E15>0),E15/(D15*(D15-E15)),0) -> 2.6986183e-05 | I15: =I14+H15 -> 0.00020833333 | J15: =G15*SQRT(I15) -> 0.013856406 | K15: =IF(OR(G15>=1,G15<=0),"",G15^EXP($B$5*SQRT(I15)/ABS(LN(G15)))) -> 0.92161107 | L15: =IF(OR(G15>=1,G15<=0),"",G15^EXP(-$B$5*SQRT(I15)/ABS(LN(G15)))) -> 0.97979295 | N15: S(5000 h) | O15: =IFERROR(LOOKUP(5000,$B$8:$B$207,$G$8:$G$207),1) -> 0.38662426 | P15: =IFERROR(LOOKUP(5000,$B$8:$B$207,$K$8:$K$207),"") -> 0.3059127 | Q15: =IFERROR(LOOKUP(5000,$B$8:$B$207,$L$8:$L$207),"") -> 0.46652766
A16: 9 | B16: =Metodo_Grafico!B16 -> 873.6 | C16: =Metodo_Grafico!C16 -> 1 | D16: =$B$4-A16+1 -> 192 | E16: =C16 -> 1 | F16: =IF(C16=1,(D16-E16)/D16,1) -> 0.99479167 | G16: =G15*F16 -> 0.955 | H16: =IF(AND(C16=1,D16-E16>0),E16/(D16*(D16-E16)),0) -> 2.7268761e-05 | I16: =I15+H16 -> 0.00023560209 | J16: =G16*SQRT(I16) -> 0.014658615 | K16: =IF(OR(G16>=1,G16<=0),"",G16^EXP($B$5*SQRT(I16)/ABS(LN(G16)))) -> 0.91530533 | L16: =IF(OR(G16>=1,G16<=0),"",G16^EXP(-$B$5*SQRT(I16)/ABS(LN(G16)))) -> 0.97632871 | N16: S(6000 h) | O16: =IFERROR(LOOKUP(6000,$B$8:$B$207,$G$8:$G$207),1) -> 0.2198319 | P16: =IFERROR(LOOKUP(6000,$B$8:$B$207,$K$8:$K$207),"") -> 0.14927588 | Q16: =IFERROR(LOOKUP(6000,$B$8:$B$207,$L$8:$L$207),"") -> 0.29921379
A17: 10 | B17: =Metodo_Grafico!B17 -> 941.7 | C17: =Metodo_Grafico!C17 -> 1 | D17: =$B$4-A17+1 -> 191 | E17: =C17 -> 1 | F17: =IF(C17=1,(D17-E17)/D17,1) -> 0.9947644 | G17: =G16*F17 -> 0.95 | H17: =IF(AND(C17=1,D17-E17>0),E17/(D17*(D17-E17)),0) -> 2.75558e-05 | I17: =I16+H17 -> 0.00026315789 | J17: =G17*SQRT(I17) -> 0.015411035 | K17: =IF(OR(G17>=1,G17<=0),"",G17^EXP($B$5*SQRT(I17)/ABS(LN(G17)))) -> 0.90906609 | L17: =IF(OR(G17>=1,G17<=0),"",G17^EXP(-$B$5*SQRT(I17)/ABS(LN(G17)))) -> 0.97278059 | N17: S(8000 h) | O17: =IFERROR(LOOKUP(8000,$B$8:$B$207,$G$8:$G$207),1) -> 0.10040399 | P17: =IFERROR(LOOKUP(8000,$B$8:$B$207,$K$8:$K$207),"") -> 0.046926287 | Q17: =IFERROR(LOOKUP(8000,$B$8:$B$207,$L$8:$L$207),"") -> 0.17780845
A18: 11 | B18: =Metodo_Grafico!B18 -> 960.8 | C18: =Metodo_Grafico!C18 -> 0 | D18: =$B$4-A18+1 -> 190 | E18: =C18 -> 0 | F18: =IF(C18=1,(D18-E18)/D18,1) -> 1 | G18: =G17*F18 -> 0.95 | H18: =IF(AND(C18=1,D18-E18>0),E18/(D18*(D18-E18)),0) -> 0 | I18: =I17+H18 -> 0.00026315789 | J18: =G18*SQRT(I18) -> 0.015411035 | K18: =IF(OR(G18>=1,G18<=0),"",G18^EXP($B$5*SQRT(I18)/ABS(LN(G18)))) -> 0.90906609 | L18: =IF(OR(G18>=1,G18<=0),"",G18^EXP(-$B$5*SQRT(I18)/ABS(LN(G18)))) -> 0.97278059
A19: 12 | B19: =Metodo_Grafico!B19 -> 1024.2 | C19: =Metodo_Grafico!C19 -> 0 | D19: =$B$4-A19+1 -> 189 | E19: =C19 -> 0 | F19: =IF(C19=1,(D19-E19)/D19,1) -> 1 | G19: =G18*F19 -> 0.95 | H19: =IF(AND(C19=1,D19-E19>0),E19/(D19*(D19-E19)),0) -> 0 | I19: =I18+H19 -> 0.00026315789 | J19: =G19*SQRT(I19) -> 0.015411035 | K19: =IF(OR(G19>=1,G19<=0),"",G19^EXP($B$5*SQRT(I19)/ABS(LN(G19)))) -> 0.90906609 | L19: =IF(OR(G19>=1,G19<=0),"",G19^EXP(-$B$5*SQRT(I19)/ABS(LN(G19)))) -> 0.97278059
A20: 13 | B20: =Metodo_Grafico!B20 -> 1073.5 | C20: =Metodo_Grafico!C20 -> 0 | D20: =$B$4-A20+1 -> 188 | E20: =C20 -> 0 | F20: =IF(C20=1,(D20-E20)/D20,1) -> 1 | G20: =G19*F20 -> 0.95 | H20: =IF(AND(C20=1,D20-E20>0),E20/(D20*(D20-E20)),0) -> 0 | I20: =I19+H20 -> 0.00026315789 | J20: =G20*SQRT(I20) -> 0.015411035 | K20: =IF(OR(G20>=1,G20<=0),"",G20^EXP($B$5*SQRT(I20)/ABS(LN(G20)))) -> 0.90906609 | L20: =IF(OR(G20>=1,G20<=0),"",G20^EXP(-$B$5*SQRT(I20)/ABS(LN(G20)))) -> 0.97278059 | N20: Lectura critica
A21: 14 | B21: =Metodo_Grafico!B21 -> 1077.1 | C21: =Metodo_Grafico!C21 -> 1 | D21: =$B$4-A21+1 -> 187 | E21: =C21 -> 1 | F21: =IF(C21=1,(D21-E21)/D21,1) -> 0.99465241 | G21: =G20*F21 -> 0.94491979 | H21: =IF(AND(C21=1,D21-E21>0),E21/(D21*(D21-E21)),0) -> 2.8750503e-05 | I21: =I20+H21 -> 0.0002919084 | J21: =G21*SQRT(I21) -> 0.016144264 | K21: =IF(OR(G21>=1,G21<=0),"",G21^EXP($B$5*SQRT(I21)/ABS(LN(G21)))) -> 0.90274627 | L21: =IF(OR(G21>=1,G21<=0),"",G21^EXP(-$B$5*SQRT(I21)/ABS(LN(G21)))) -> 0.96911472 | N21: La curva baja solo en los tiempos de falla. Las censuras no producen escalones, pero reducen n(j), lo que hace mayores los saltos posteriores: asi es como aportan informacion. Al final de la curva quedan pocas unidades en riesgo, por lo que los ultimos escalones son inestables y sus intervalos son muy anchos. Como la ultima observacion es censurada, S(t) queda indefinida mas alla del ultimo tiempo: Kaplan-Meier no extrapola, y para eso se necesita el modelo Weibull.
A22: 15 | B22: =Metodo_Grafico!B22 -> 1099.2 | C22: =Metodo_Grafico!C22 -> 1 | D22: =$B$4-A22+1 -> 186 | E22: =C22 -> 1 | F22: =IF(C22=1,(D22-E22)/D22,1) -> 0.99462366 | G22: =G21*F22 -> 0.93983957 | H22: =IF(AND(C22=1,D22-E22>0),E22/(D22*(D22-E22)),0) -> 2.9061319e-05 | I22: =I21+H22 -> 0.00032096972 | J22: =G22*SQRT(I22) -> 0.016837816 | K22: =IF(OR(G22>=1,G22<=0),"",G22^EXP($B$5*SQRT(I22)/ABS(LN(G22)))) -> 0.89648936 | L22: =IF(OR(G22>=1,G22<=0),"",G22^EXP(-$B$5*SQRT(I22)/ABS(LN(G22)))) -> 0.9653818
A23: 16 | B23: =Metodo_Grafico!B23 -> 1133.3 | C23: =Metodo_Grafico!C23 -> 0 | D23: =$B$4-A23+1 -> 185 | E23: =C23 -> 0 | F23: =IF(C23=1,(D23-E23)/D23,1) -> 1 | G23: =G22*F23 -> 0.93983957 | H23: =IF(AND(C23=1,D23-E23>0),E23/(D23*(D23-E23)),0) -> 0 | I23: =I22+H23 -> 0.00032096972 | J23: =G23*SQRT(I23) -> 0.016837816 | K23: =IF(OR(G23>=1,G23<=0),"",G23^EXP($B$5*SQRT(I23)/ABS(LN(G23)))) -> 0.89648936 | L23: =IF(OR(G23>=1,G23<=0),"",G23^EXP(-$B$5*SQRT(I23)/ABS(LN(G23)))) -> 0.9653818
A24: 17 | B24: =Metodo_Grafico!B24 -> 1161.6 | C24: =Metodo_Grafico!C24 -> 1 | D24: =$B$4-A24+1 -> 184 | E24: =C24 -> 1 | F24: =IF(C24=1,(D24-E24)/D24,1) -> 0.99456522 | G24: =G23*F24 -> 0.93473175 | H24: =IF(AND(C24=1,D24-E24>0),E24/(D24*(D24-E24)),0) -> 2.9698266e-05 | I24: =I23+H24 -> 0.00035066798 | J24: =G24*SQRT(I24) -> 0.017503909 | K24: =IF(OR(G24>=1,G24<=0),"",G24^EXP($B$5*SQRT(I24)/ABS(LN(G24)))) -> 0.89024261 | L24: =IF(OR(G24>=1,G24<=0),"",G24^EXP(-$B$5*SQRT(I24)/ABS(LN(G24)))) -> 0.96157304
A25: 18 | B25: =Metodo_Grafico!B25 -> 1196.6 | C25: =Metodo_Grafico!C25 -> 0 | D25: =$B$4-A25+1 -> 183 | E25: =C25 -> 0 | F25: =IF(C25=1,(D25-E25)/D25,1) -> 1 | G25: =G24*F25 -> 0.93473175 | H25: =IF(AND(C25=1,D25-E25>0),E25/(D25*(D25-E25)),0) -> 0 | I25: =I24+H25 -> 0.00035066798 | J25: =G25*SQRT(I25) -> 0.017503909 | K25: =IF(OR(G25>=1,G25<=0),"",G25^EXP($B$5*SQRT(I25)/ABS(LN(G25)))) -> 0.89024261 | L25: =IF(OR(G25>=1,G25<=0),"",G25^EXP(-$B$5*SQRT(I25)/ABS(LN(G25)))) -> 0.96157304
A26: 19 | B26: =Metodo_Grafico!B26 -> 1230.9 | C26: =Metodo_Grafico!C26 -> 1 | D26: =$B$4-A26+1 -> 182 | E26: =C26 -> 1 | F26: =IF(C26=1,(D26-E26)/D26,1) -> 0.99450549 | G26: =G25*F26 -> 0.92959586 | H26: =IF(AND(C26=1,D26-E26>0),E26/(D26*(D26-E26)),0) -> 3.0356384e-05 | I26: =I25+H26 -> 0.00038102437 | J26: =G26*SQRT(I26) -> 0.018145568 | K26: =IF(OR(G26>=1,G26<=0),"",G26^EXP($B$5*SQRT(I26)/ABS(LN(G26)))) -> 0.88400292 | L26: =IF(OR(G26>=1,G26<=0),"",G26^EXP(-$B$5*SQRT(I26)/ABS(LN(G26)))) -> 0.9576931
A27: 20 | B27: =Metodo_Grafico!B27 -> 1240.7 | C27: =Metodo_Grafico!C27 -> 0 | D27: =$B$4-A27+1 -> 181 | E27: =C27 -> 0 | F27: =IF(C27=1,(D27-E27)/D27,1) -> 1 | G27: =G26*F27 -> 0.92959586 | H27: =IF(AND(C27=1,D27-E27>0),E27/(D27*(D27-E27)),0) -> 0 | I27: =I26+H27 -> 0.00038102437 | J27: =G27*SQRT(I27) -> 0.018145568 | K27: =IF(OR(G27>=1,G27<=0),"",G27^EXP($B$5*SQRT(I27)/ABS(LN(G27)))) -> 0.88400292 | L27: =IF(OR(G27>=1,G27<=0),"",G27^EXP(-$B$5*SQRT(I27)/ABS(LN(G27)))) -> 0.9576931
A28: 21 | B28: =Metodo_Grafico!B28 -> 1265.2 | C28: =Metodo_Grafico!C28 -> 0 | D28: =$B$4-A28+1 -> 180 | E28: =C28 -> 0 | F28: =IF(C28=1,(D28-E28)/D28,1) -> 1 | G28: =G27*F28 -> 0.92959586 | H28: =IF(AND(C28=1,D28-E28>0),E28/(D28*(D28-E28)),0) -> 0 | I28: =I27+H28 -> 0.00038102437 | J28: =G28*SQRT(I28) -> 0.018145568 | K28: =IF(OR(G28>=1,G28<=0),"",G28^EXP($B$5*SQRT(I28)/ABS(LN(G28)))) -> 0.88400292 | L28: =IF(OR(G28>=1,G28<=0),"",G28^EXP(-$B$5*SQRT(I28)/ABS(LN(G28)))) -> 0.9576931
A29: 22 | B29: =Metodo_Grafico!B29 -> 1308.3 | C29: =Metodo_Grafico!C29 -> 0 | D29: =$B$4-A29+1 -> 179 | E29: =C29 -> 0 | F29: =IF(C29=1,(D29-E29)/D29,1) -> 1 | G29: =G28*F29 -> 0.92959586 | H29: =IF(AND(C29=1,D29-E29>0),E29/(D29*(D29-E29)),0) -> 0 | I29: =I28+H29 -> 0.00038102437 | J29: =G29*SQRT(I29) -> 0.018145568 | K29: =IF(OR(G29>=1,G29<=0),"",G29^EXP($B$5*SQRT(I29)/ABS(LN(G29)))) -> 0.88400292 | L29: =IF(OR(G29>=1,G29<=0),"",G29^EXP(-$B$5*SQRT(I29)/ABS(LN(G29)))) -> 0.9576931
A30: 23 | B30: =Metodo_Grafico!B30 -> 1360.3 | C30: =Metodo_Grafico!C30 -> 1 | D30: =$B$4-A30+1 -> 178 | E30: =C30 -> 1 | F30: =IF(C30=1,(D30-E30)/D30,1) -> 0.99438202 | G30: =G29*F30 -> 0.92437341 | H30: =IF(AND(C30=1,D30-E30>0),E30/(D30*(D30-E30)),0) -> 3.1739986e-05 | I30: =I29+H30 -> 0.00041276435 | J30: =G30*SQRT(I30) -> 0.018780128 | K30: =IF(OR(G30>=1,G30<=0),"",G30^EXP($B$5*SQRT(I30)/ABS(LN(G30)))) -> 0.87767279 | L30: =IF(OR(G30>=1,G30<=0),"",G30^EXP(-$B$5*SQRT(I30)/ABS(LN(G30)))) -> 0.95371097
A31: 24 | B31: =Metodo_Grafico!B31 -> 1392.9 | C31: =Metodo_Grafico!C31 -> 1 | D31: =$B$4-A31+1 -> 177 | E31: =C31 -> 1 | F31: =IF(C31=1,(D31-E31)/D31,1) -> 0.99435028 | G31: =G30*F31 -> 0.91915096 | H31: =IF(AND(C31=1,D31-E31>0),E31/(D31*(D31-E31)),0) -> 3.2100668e-05 | I31: =I30+H31 -> 0.00044486502 | J31: =G31*SQRT(I31) -> 0.01938657 | K31: =IF(OR(G31>=1,G31<=0),"",G31^EXP($B$5*SQRT(I31)/ABS(LN(G31)))) -> 0.8713941 | L31: =IF(OR(G31>=1,G31<=0),"",G31^EXP(-$B$5*SQRT(I31)/ABS(LN(G31)))) -> 0.94968099
A32: 25 | B32: =Metodo_Grafico!B32 -> 1441.9 | C32: =Metodo_Grafico!C32 -> 1 | D32: =$B$4-A32+1 -> 176 | E32: =C32 -> 1 | F32: =IF(C32=1,(D32-E32)/D32,1) -> 0.99431818 | G32: =G31*F32 -> 0.91392851 | H32: =IF(AND(C32=1,D32-E32>0),E32/(D32*(D32-E32)),0) -> 3.2467532e-05 | I32: =I31+H32 -> 0.00047733255 | J32: =G32*SQRT(I32) -> 0.019967457 | K32: =IF(OR(G32>=1,G32<=0),"",G32^EXP($B$5*SQRT(I32)/ABS(LN(G32)))) -> 0.86516223 | L32: =IF(OR(G32>=1,G32<=0),"",G32^EXP(-$B$5*SQRT(I32)/ABS(LN(G32)))) -> 0.94560713
A33: 26 | B33: =Metodo_Grafico!B33 -> 1442.2 | C33: =Metodo_Grafico!C33 -> 1 | D33: =$B$4-A33+1 -> 175 | E33: =C33 -> 1 | F33: =IF(C33=1,(D33-E33)/D33,1) -> 0.99428571 | G33: =G32*F33 -> 0.90870607 | H33: =IF(AND(C33=1,D33-E33>0),E33/(D33*(D33-E33)),0) -> 3.2840722e-05 | I33: =I32+H33 -> 0.00051017328 | J33: =G33*SQRT(I33) -> 0.020524958 | K33: =IF(OR(G33>=1,G33<=0),"",G33^EXP($B$5*SQRT(I33)/ABS(LN(G33)))) -> 0.85897325 | L33: =IF(OR(G33>=1,G33<=0),"",G33^EXP(-$B$5*SQRT(I33)/ABS(LN(G33)))) -> 0.94149278
... A207: 200 | B207: =Metodo_Grafico!B207 -> 9165.7 | C207: =Metodo_Grafico!C207 -> 0 | D207: =$B$4-A207+1 -> 1 | E207: =C207 -> 0 | F207: =IF(C207=1,(D207-E207)/D207,1) -> 1 | G207: =G206*F207 -> 0.075302996 | H207: =IF(AND(C207=1,D207-E207>0),E207/(D207*(D207-E207)),0) -> 0 | I207: =I206+H207 -> 0.19572607 | J207: =G207*SQRT(I207) -> 0.033314753 | K207: =IF(OR(G207>=1,G207<=0),"",G207^EXP($B$5*SQRT(I207)/ABS(LN(G207)))) -> 0.026879101 | L207: =IF(OR(G207>=1,G207<=0),"",G207^EXP(-$B$5*SQRT(I207)/ABS(LN(G207)))) -> 0.15731276

Sheet Comparacion
A1: prematuras
A2: Metodo grafico (regresion de rangos), maxima verosimilitud y estimador no parametrico de Kaplan-Meier.
A4: Concepto | B4: Metodo grafico (RRY) | C4: Maxima verosimilitud (MLE) | D4: Kaplan-Meier | E4: Comentario | I4: Resumen de bondad de ajuste
A5: Parametro de forma BETA | B5: =Metodo_Grafico!$P$15 -> 1.9091803 | C5: =Max_Verosimilitud!$I$5 -> 1.9476758 | D5: No aplica | E5: BETA > 1 indica desgaste progresivo | I5: R cuadrado del papel Weibull | J5: =Metodo_Grafico!$P$19 -> 0.98984743
A6: Parametro de escala ETA (h) | B6: =Metodo_Grafico!$P$16 -> 5123.1482 | C6: =Max_Verosimilitud!$I$6 -> 5099.776 | D6: No aplica | E6: Vida caracteristica: 63.2% han fallado | I6: Kolmogorov-Smirnov D | J6: =Max_Verosimilitud!$N$13 -> 0.049058692
A7: Error estandar de BETA | B7: No disponible | C7: =Max_Verosimilitud!$I$28 -> 0.13715431 | D7: No aplica | E7: Solo MLE entrega inferencia formal | I7: K-S valor critico (5%) | J7: =Max_Verosimilitud!$N$14 -> 0.12312861
A8: IC 95% de BETA — inferior | B8: No disponible | C8: =Max_Verosimilitud!$I$30 -> 1.6965845 | D8: No aplica | E8: Escala logaritmica | I8: Prueba LR contra exponencial | J8: =Max_Verosimilitud!$N$8 -> 65.325944
A9: IC 95% de BETA — superior | B9: No disponible | C9: =Max_Verosimilitud!$I$31 -> 2.2359281 | D9: No aplica | E9: Escala logaritmica | I9: valor p de la prueba LR | J9: =Max_Verosimilitud!$N$9 -> 6.3480105e-16
